Workbook

Sheet PARTIDOS
B2: 46184 | C2: MÉXICO | D2: SUDAFRICA | E2: PUNTOS | G2: 46184 | H2: COREA SUR | I2: R. CHECA | J2: PUNTOS | L2: 12 de junio de 2026 | M2: CANADA | N2: BOSNIA | O2: PUNTOS | R2: EEUU | S2: PARAGUAY | T2: PUNTOS | W2: CATAR | X2: SUIZA | Y2: PUNTOS | AB2: BRASIL | AC2: MARRUECOS | AD2: PUNTOS | AG2: HAITI | AH2: ESCOCIA | AI2: PUNTOS | AL2: AUTRALIA | AM2: TURQUIA | AN2: PUNTOS | AQ2: ALEMANIA | AR2: CURAZAO | AS2: PUNTOS | AV2: HOLANDA | AW2: JAPON | AX2: PUNTOS | BA2: COSTA MARF | BB2: ECUADOR | BC2: PUNTOS | BF2: SUECIA | BG2: TUNEZ | BH2: PUNTOS | BK2: ESPAÑA | BL2: C. VERDE | BM2: PUNTOS | BP2: BELGICA | BQ2: EGIPTO | BR2: PUNTOS | BU2: ARABIA SAU | BV2: URUGUAY | BW2: PUNTOS | BZ2: IRAN | CA2: N. ZELANDA | CB2: PUNTOS | CE2: FRANCIA | CF2: SENEGAL | CG2: PUNTOS | CJ2: IRAK | CK2: NORUEGA | CL2: PUNTOS | CO2: ARGENTINA | CP2: ARGELIA | CQ2: PUNTOS | CT2: AUSTRALIA | CU2: JORDANIA | CV2: PUNTOS | CY2: PORTUGAL | CZ2: CONGO | DA2: PUNTOS | DD2: INGLATERRA | DE2: CROACIA | DF2: PUNTOS | DI2: GHANA | DJ2: PANAMA | DK2: PUNTOS | DN2: UZBEKISTAN | DO2: COLOMBIA | DP2: PUNTOS | DS2: REPUBLICA C | DT2: S. AFRICA | DU2: PUNTOS | DX2: SUIZA | DY2: BOSNIA | DZ2: PUNTOS | EC2: CANADA | ED2: CATAR | EE2: PUNTOS | EH2: MEXICO | EI2: COREA SUR | EJ2: PUNTOS | EM2: EEUU | EN2: AUSTRALIA | EO2: PUNTOS | ER2: ESCOCIA | ES2: MARRUECOS | ET2: PUNTOS | EW2: BRASIL | EX2: HAITÍ | EY2: PUNTOS | FB2: TURQUÍA | FC2: PARAGUAY | FD2: PUNTOS | FG2: HOLANDA | FH2: SUECIA | FI2: PUNTOS | FL2: ALEMANIA | FM2: CASTA MAR | FN2: PUNTOS | FQ2: ECUADOR | FR2: CURAZAO | FS2: PUNTOS | FV2: TÚNEZ | FW2: JAPÓN | FX2: PUNTOS | GA2: ESPAÑA | GB2: ARABIA SAU | GC2: PUNTOS | GF2: BÉLGICA | GG2: IRAN | GH2: PUNTOS | GK2: URUGUAY | GL2: C. VERDE | GM2: PUNTOS | GP2: N. ZELANDA | GQ2: EGIPTO | GR2: PUNTOS | GU2: ARGENTINA | GV2: AUSTRALIA | GW2: PUNTOS | GZ2: FRANCIA | HA2: IRAK | HB2: PUNTOS | HE2: NORUEGA | HF2: SENEGAL | HG2: PUNTOS | HJ2: JORDANIA | HK2: ARGELIA | HL2: PUNTOS | HO2: PORTUGAL | HP2: UZBEKISTÁN | HQ2: PUNTOS | HT2: INGLATERRA | HU2: GHANA | HV2: PUNTOS | HY2: PANAMA | HZ2: CROACIA | IA2: PUNTOS | ID2: COLOMBIA | IE2: CONGO | IF2: PUNTOS | II2: SUIZA | IJ2: CANADA | IK2: PUNTOS | IN2: BOSNIA | IO2: CATAR | IP2: PUNTOS | IS2: MARRUECOS | IT2: HAITÍ | IU2: PUNTOS | IX2: ESCOCIA | IY2: BRASIL | IZ2: PUNTOS | JC2: S. AFRICA | JD2: COREA S | JE2: PUNTOS | JH2: R. CHECA | JI2: MEXICO | JJ2: PUNTOS | JM2: CORAZAO | JN2: COSTA MA | JO2: PUNTOS | JR2: ECUADOR | JS2: ALEMANIA | JT2: PUNTOS | JW2: TUNEZ | JX2: HOLANDA | JY2: PUNTOS | KB2: JAPON | KC2: SUECIA | KD2: PUNTOS | KG2: TURQUIA | KH2: EEUU | KI2: PUNTOS | KL2: PARAGUAY | KM2: AUSTRALIA | KN2: PUNTOS | KQ2: NORUEGA | KR2: FRANCIA | KS2: PUNTOS | KV2: SENEGAL | KW2: IRAK | KX2: PUNTOS | LA2: C. VERDE | LB2: ARABIA SAU | LC2: PUNTOS | LF2: URUGUAY | LG2: ESPAÑA | LH2: PUNTOS | LK2: N. ZELANDA | LL2: BELGICA | LM2: PUNTOS | LP2: EGIPTO | LQ2: IRAN | LR2: PUNTOS | LU2: PANAMA | LV2: INGLATERRA | LW2: PUNTOS | LZ2: CROACIA | MA2: GHANA | MB2: PUNTOS | ME2: COLOMBIA | MF2: PORTUGAL | MG2: PUNTOS | MJ2: CONGO | MK2: UZBEKISTAN | ML2: PUNTOS | MO2: ARGELIA | MP2: AUSTRIA | MQ2: PUNTOS | MT2: JORDANIA | MU2: ARGENTINA | MV2: PUNTOS | MY2: CAMPEON | MZ2: puntos | NA2: SEGUNDO | NB2: puntos | NC2: TERCERO | ND2: puntos | NE2: CUARTO | NF2: puntos | NG2: GOLEADOR | NH2: puntos | NI2: TOTAL
C3: 2 | D3: 0 | H3: 2 | I3: 1 | M3: 1 | N3: 1 | R3: 4 | S3: 1 | W3: 1 | X3: 1 | AB3: 1 | AC3: 1
A4: 1 | B4: RUBELIO MEJIA | C4: 2 | D4: 1 | E4: =IF(OR(C$3="",D$3="",C4="",D4=""), "", IF(AND(C$3=C4,D$3=D4), 3, IF(AND(C$3=D$3,C4=D4), 2, IF(OR(AND(C$3>D$3,C4>D4), AND(C$3<D$3,C4<D4)), 1, 0)))) -> 1 | G4: RUBELIO MEJIA | H4: 2 | I4: 2 | J4: =IF(OR(H$3="",I$3="",H4="",I4=""), "", IF(AND(H$3=H4,I$3=I4), 3, IF(AND(H$3=I$3,H4=I4), 2, IF(OR(AND(H$3>I$3,H4>I4), AND(H$3<I$3,H4<I4)), 1, 0)))) -> 0 | L4: RUBELIO MEJIA | M4: 1 | N4: 1 | O4: =IF(OR(M$3="",N$3="",M4="",N4=""), "", IF(AND(M$3=M4,N$3=N4), 3, IF(AND(M$3=N$3,M4=N4), 2, IF(OR(AND(M$3>N$3,M4>N4), AND(M$3<N$3,M4<N4)), 1, 0)))) -> 3 | Q4: RUBELIO MEJIA | R4: 1 | S4: 1 | T4: =IF(OR(R$3="",S$3="",R4="",S4=""), "", IF(AND(R$3=R4,S$3=S4), 3, IF(AND(R$3=S$3,R4=S4), 2, IF(OR(AND(R$3>S$3,R4>S4), AND(R$3<S$3,R4<S4)), 1, 0)))) -> 0 | V4: RUBELIO MEJIA | W4: 1 | X4: 3 | Y4: =IF(OR(W$3="",X$3="",W4="",X4=""), "", IF(AND(W$3=W4,X$3=X4), 3, IF(AND(W$3=X$3,W4=X4), 2, IF(OR(AND(W$3>X$3,W4>X4), AND(W$3<X$3,W4<X4)), 1, 0)))) -> 0 | AA4: RUBELIO MEJIA | AB4: 3 | AC4: 1 | AD4: =IF(OR(AB$3="",AC$3="",AB4="",AC4=""), "", IF(AND(AB$3=AB4,AC$3=AC4), 3, IF(AND(AB$3=AC$3,AB4=AC4), 2, IF(OR(AND(AB$3>AC$3,AB4>AC4), AND(AB$3<AC$3,AB4<AC4)), 1, 0)))) -> 0 | AF4: RUBELIO MEJIA | AG4: 0 | AH4: 2 | AI4: =IF(OR(AG$3="",AH$3="",AG4="",AH4=""), "", IF(AND(AG$3=AG4,AH$3=AH4), 3, IF(AND(AG$3=AH$3,AG4=AH4), 2, IF(OR(AND(AG$3>AH$3,AG4>AH4), AND(AG$3<AH$3,AG4<AH4)), 1, 0)))) | AK4: RUBELIO MEJIA | AL4: 1 | AM4: 3 | AN4: =IF(OR(AL$3="",AM$3="",AL4="",AM4=""), "", IF(AND(AL$3=AL4,AM$3=AM4), 3, IF(AND(AL$3=AM$3,AL4=AM4), 2, IF(OR(AND(AL$3>AM$3,AL4>AM4), AND(AL$3<AM$3,AL4<AM4)), 1, 0)))) | AP4: RUBELIO MEJIA | AQ4: 4 | AR4: 0 | AS4: =IF(OR(AQ$3="",AR$3="",AQ4="",AR4=""), "", IF(AND(AQ$3=AQ4,AR$3=AR4), 3, IF(AND(AQ$3=AR$3,AQ4=AR4), 2, IF(OR(AND(AQ$3>AR$3,AQ4>AR4), AND(AQ$3<AR$3,AQ4<AR4)), 1, 0)))) | AU4: RUBELIO MEJIA | AV4: 3 | AW4: 1 | AX4: =IF(OR(AV$3="",AW$3="",AV4="",AW4=""), "", IF(AND(AV$3=AV4,AW$3=AW4), 3, IF(AND(AV$3=AW$3,AV4=AW4), 2, IF(OR(AND(AV$3>AW$3,AV4>AW4), AND(AV$3<AW$3,AV4<AW4)), 1, 0)))) | AZ4: RUBELIO MEJIA | BA4: 1 | BB4: 1 | BC4: =IF(OR(BA$3="",BB$3="",BA4="",BB4=""), "", IF(AND(BA$3=BA4,BB$3=BB4), 3, IF(AND(BA$3=BB$3,BA4=BB4), 2, IF(OR(AND(BA$3>BB$3,BA4>BB4), AND(BA$3<BB$3,BA4<BB4)), 1, 0)))) | BE4: RUBELIO MEJIA | BF4: 2 | BG4: 1 | BH4: =IF(OR(BF$3="",BG$3="",BF4="",BG4=""), "", IF(AND(BF$3=BF4,BG$3=BG4), 3, IF(AND(BF$3=BG$3,BF4=BG4), 2, IF(OR(AND(BF$3>BG$3,BF4>BG4), AND(BF$3<BG$3,BF4<BG4)), 1, 0)))) | BJ4: RUBELIO MEJIA | BK4: 4 | BL4: 1 | BM4: =IF(OR(BK$3="",BL$3="",BK4="",BL4=""), "", IF(AND(BK$3=BK4,BL$3=BL4), 3, IF(AND(BK$3=BL$3,BK4=BL4), 2, IF(OR(AND(BK$3>BL$3,BK4>BL4), AND(BK$3<BL$3,BK4<BL4)), 1, 0)))) | BO4: RUBELIO MEJIA | BP4: 3 | BQ4: 1 | BR4: =IF(OR(BP$3="",BQ$3="",BP4="",BQ4=""), "", IF(AND(BP$3=BP4,BQ$3=BQ4), 3, IF(AND(BP$3=BQ$3,BP4=BQ4), 2, IF(OR(AND(BP$3>BQ$3,BP4>BQ4), AND(BP$3<BQ$3,BP4<BQ4)), 1, 0)))) | BT4: RUBELIO MEJIA | BU4: 0 | BV4: 2 | BW4: =IF(OR(BU$3="",BV$3="",BU4="",BV4=""), "", IF(AND(BU$3=BU4,BV$3=BV4), 3, IF(AND(BU$3=BV$3,BU4=BV4), 2, IF(OR(AND(BU$3>BV$3,BU4>BV4), AND(BU$3<BV$3,BU4<BV4)), 1, 0)))) | BY4: RUBELIO MEJIA | BZ4: 2 | CA4: 0 | CB4: =IF(OR(BZ$3="",CA$3="",BZ4="",CA4=""), "", IF(AND(BZ$3=BZ4,CA$3=CA4), 3, IF(AND(BZ$3=CA$3,BZ4=CA4), 2, IF(OR(AND(BZ$3>CA$3,BZ4>CA4), AND(BZ$3<CA$3,BZ4<CA4)), 1, 0)))) | CD4: RUBELIO MEJIA | CE4: 3 | CF4: 1 | CG4: =IF(OR(CE$3="",CF$3="",CE4="",CF4=""), "", IF(AND(CE$3=CE4,CF$3=CF4), 3, IF(AND(CE$3=CF$3,CE4=CF4), 2, IF(OR(AND(CE$3>CF$3,CE4>CF4), AND(CE$3<CF$3,CE4<CF4)), 1, 0)))) | CI4: RUBELIO MEJIA | CJ4: 1 | CK4: 3 | CL4: =IF(OR(CJ$3="",CK$3="",CJ4="",CK4=""), "", IF(AND(CJ$3=CJ4,CK$3=CK4), 3, IF(AND(CJ$3=CK$3,CJ4=CK4), 2, IF(OR(AND(CJ$3>CK$3,CJ4>CK4), AND(CJ$3<CK$3,CJ4<CK4)), 1, 0)))) | CN4: RUBELIO MEJIA | CO4: 3 | CP4: 1 | CQ4: =IF(OR(CO$3="",CP$3="",CO4="",CP4=""), "", IF(AND(CO$3=CO4,CP$3=CP4), 3, IF(AND(CO$3=CP$3,CO4=CP4), 2, IF(OR(AND(CO$3>CP$3,CO4>CP4), AND(CO$3<CP$3,CO4<CP4)), 1, 0)))) | CS4: RUBELIO MEJIA | CT4: 2 | CU4: 0 | CV4: =IF(OR(CT$3="",CU$3="",CT4="",CU4=""), "", IF(AND(CT$3=CT4,CU$3=CU4), 3, IF(AND(CT$3=CU$3,CT4=CU4), 2, IF(OR(AND(CT$3>CU$3,CT4>CU4), AND(CT$3<CU$3,CT4<CU4)), 1, 0)))) | CX4: RUBELIO MEJIA | CY4: 3 | CZ4: 1 | DA4: =IF(OR(CY$3="",CZ$3="",CY4="",CZ4=""), "", IF(AND(CY$3=CY4,CZ$3=CZ4), 3, IF(AND(CY$3=CZ$3,CY4=CZ4), 2, IF(OR(AND(CY$3>CZ$3,CY4>CZ4), AND(CY$3<CZ$3,CY4<CZ4)), 1, 0)))) | DC4: RUBELIO MEJIA | DD4: 2 | DE4: 1 | DF4: =IF(OR(DD$3="",DE$3="",DD4="",DE4=""), "", IF(AND(DD$3=DD4,DE$3=DE4), 3, IF(AND(DD$3=DE$3,DD4=DE4), 2, IF(OR(AND(DD$3>DE$3,DD4>DE4), AND(DD$3<DE$3,DD4<DE4)), 1, 0)))) | DH4: RUBELIO MEJIA | DI4: 2 | DJ4: 0 | DK4: =IF(OR(DI$3="",DJ$3="",DI4="",DJ4=""), "", IF(AND(DI$3=DI4,DJ$3=DJ4), 3, IF(AND(DI$3=DJ$3,DI4=DJ4), 2, IF(OR(AND(DI$3>DJ$3,DI4>DJ4), AND(DI$3<DJ$3,DI4<DJ4)), 1, 0)))) | DM4: RUBELIO MEJIA | DN4: 0 | DO4: 3 | DP4: =IF(OR(DN$3="",DO$3="",DN4="",DO4=""), "", IF(AND(DN$3=DN4,DO$3=DO4), 3, IF(AND(DN$3=DO$3,DN4=DO4), 2, IF(OR(AND(DN$3>DO$3,DN4>DO4), AND(DN$3<DO$3,DN4<DO4)), 1, 0)))) | DR4: RUBELIO MEJIA | DS4: 2 | DT4: 1 | DU4: =IF(OR(DS$3="",DT$3="",DS4="",DT4=""), "", IF(AND(DS$3=DS4,DT$3=DT4), 3, IF(AND(DS$3=DT$3,DS4=DT4), 2, IF(OR(AND(DS$3>DT$3,DS4>DT4), AND(DS$3<DT$3,DS4<DT4)), 1, 0)))) | DW4: RUBELIO MEJIA | DX4: 2 | DY4: 1 | DZ4: =IF(OR(DX$3="",DY$3="",DX4="",DY4=""), "", IF(AND(DX$3=DX4,DY$3=DY4), 3, IF(AND(DX$3=DY$3,DX4=DY4), 2, IF(OR(AND(DX$3>DY$3,DX4>DY4), AND(DX$3<DY$3,DX4<DY4)), 1, 0)))) | EB4: RUBELIO MEJIA | EC4: 2 | ED4: 1 | EE4: =IF(OR(EC$3="",ED$3="",EC4="",ED4=""), "", IF(AND(EC$3=EC4,ED$3=ED4), 3, IF(AND(EC$3=ED$3,EC4=ED4), 2, IF(OR(AND(EC$3>ED$3,EC4>ED4), AND(EC$3<ED$3,EC4<ED4)), 1, 0)))) | EG4: RUBELIO MEJIA | EH4: 2 | EI4: 1 | EJ4: =IF(OR(EH$3="",EI$3="",EH4="",EI4=""), "", IF(AND(EH$3=EH4,EI$3=EI4), 3, IF(AND(EH$3=EI$3,EH4=EI4), 2, IF(OR(AND(EH$3>EI$3,EH4>EI4), AND(EH$3<EI$3,EH4<EI4)), 1, 0)))) | EL4: RUBELIO MEJIA | EM4: 2 | EN4: 0 | EO4: =IF(OR(EM$3="",EN$3="",EM4="",EN4=""), "", IF(AND(EM$3=EM4,EN$3=EN4), 3, IF(AND(EM$3=EN$3,EM4=EN4), 2, IF(OR(AND(EM$3>EN$3,EM4>EN4), AND(EM$3<EN$3,EM4<EN4)), 1, 0)))) | EQ4: RUBELIO MEJIA | ER4: 1 | ES4: 1 | ET4: =IF(OR(ER$3="",ES$3="",ER4="",ES4=""), "", IF(AND(ER$3=ER4,ES$3=ES4), 3, IF(AND(ER$3=ES$3,ER4=ES4), 2, IF(OR(AND(ER$3>ES$3,ER4>ES4), AND(ER$3<ES$3,ER4<ES4)), 1, 0)))) | EV4: RUBELIO MEJIA | EW4: 4 | EX4: 0 | EY4: =IF(OR(EW$3="",EX$3="",EW4="",EX4=""), "", IF(AND(EW$3=EW4,EX$3=EX4), 3, IF(AND(EW$3=EX$3,EW4=EX4), 2, IF(OR(AND(EW$3>EX$3,EW4>EX4), AND(EW$3<EX$3,EW4<EX4)), 1, 0)))) | FA4: RUBELIO MEJIA | FB4: 1 | FC4: 1 | FD4: =IF(OR(FB$3="",FC$3="",FB4="",FC4=""), "", IF(AND(FB$3=FB4,FC$3=FC4), 3, IF(AND(FB$3=FC$3,FB4=FC4), 2, IF(OR(AND(FB$3>FC$3,FB4>FC4), AND(FB$3<FC$3,FB4<FC4)), 1, 0)))) | FF4: RUBELIO MEJIA | FG4: 2 | FH4: 1 | FI4: =IF(OR(FG$3="",FH$3="",FG4="",FH4=""), "", IF(AND(FG$3=FG4,FH$3=FH4), 3, IF(AND(FG$3=FH$3,FG4=FH4), 2, IF(OR(AND(FG$3>FH$3,FG4>FH4), AND(FG$3<FH$3,FG4<FH4)), 1, 0)))) | FK4: RUBELIO MEJIA | FL4: 3 | FM4: 1 | FN4: =IF(OR(FL$3="",FM$3="",FL4="",FM4=""), "", IF(AND(FL$3=FL4,FM$3=FM4), 3, IF(AND(FL$3=FM$3,FL4=FM4), 2, IF(OR(AND(FL$3>FM$3,FL4>FM4), AND(FL$3<FM$3,FL4<FM4)), 1, 0)))) | FP4: RUBELIO MEJIA | FQ4: 2 | FR4: 0 | FS4: =IF(OR(FQ$3="",FR$3="",FQ4="",FR4=""), "", IF(AND(FQ$3=FQ4,FR$3=FR4), 3, IF(AND(FQ$3=FR$3,FQ4=FR4), 2, IF(OR(AND(FQ$3>FR$3,FQ4>FR4), AND(FQ$3<FR$3,FQ4<FR4)), 1, 0)))) | FU4: RUBELIO MEJIA | FV4: 2 | FW4: 2 | FX4: =IF(OR(FV$3="",FW$3="",FV4="",FW4=""), "", IF(AND(FV$3=FV4,FW$3=FW4), 3, IF(AND(FV$3=FW$3,FV4=FW4), 2, IF(OR(AND(FV$3>FW$3,FV4>FW4), AND(FV$3<FW$3,FV4<FW4)), 1, 0)))) | FZ4: RUBELIO MEJIA | GA4: 3 | GB4: 0 | GC4: =IF(OR(GA$3="",GB$3="",GA4="",GB4=""), "", IF(AND(GA$3=GA4,GB$3=GB4), 3, IF(AND(GA$3=GB$3,GA4=GB4), 2, IF(OR(AND(GA$3>GB$3,GA4>GB4), AND(GA$3<GB$3,GA4<GB4)), 1, 0)))) | GE4: RUBELIO MEJIA | GF4: 2 | GG4: 1 | GH4: =IF(OR(GF$3="",GG$3="",GF4="",GG4=""), "", IF(AND(GF$3=GF4,GG$3=GG4), 3, IF(AND(GF$3=GG$3,GF4=GG4), 2, IF(OR(AND(GF$3>GG$3,GF4>GG4), AND(GF$3<GG$3,GF4<GG4)), 1, 0)))) | GJ4: RUBELIO MEJIA | GK4: 3 | GL4: 0 | GM4: =IF(OR(GK$3="",GL$3="",GK4="",GL4=""), "", IF(AND(GK$3=GK4,GL$3=GL4), 3, IF(AND(GK$3=GL$3,GK4=GL4), 2, IF(OR(AND(GK$3>GL$3,GK4>GL4), AND(GK$3<GL$3,GK4<GL4)), 1, 0)))) | GO4: RUBELIO MEJIA | GP4: 0 | GQ4: 2 | GR4: =IF(OR(GP$3="",GQ$3="",GP4="",GQ4=""), "", IF(AND(GP$3=GP4,GQ$3=GQ4), 3, IF(AND(GP$3=GQ$3,GP4=GQ4), 2, IF(OR(AND(GP$3>GQ$3,GP4>GQ4), AND(GP$3<GQ$3,GP4<GQ4)), 1, 0)))) | GT4: RUBELIO MEJIA | GU4: 2 | GV4: 1 | GW4: =IF(OR(GU$3="",GV$3="",GU4="",GV4=""), "", IF(AND(GU$3=GU4,GV$3=GV4), 3, IF(AND(GU$3=GV$3,GU4=GV4), 2, IF(OR(AND(GU$3>GV$3,GU4>GV4), AND(GU$3<GV$3,GU4<GV4)), 1, 0)))) | GY4: RUBELIO MEJIA | GZ4: 4 | HA4: 0 | HB4: =IF(OR(GZ$3="",HA$3="",GZ4="",HA4=""), "", IF(AND(GZ$3=GZ4,HA$3=HA4), 3, IF(AND(GZ$3=HA$3,GZ4=HA4), 2, IF(OR(AND(GZ$3>HA$3,GZ4>HA4), AND(GZ$3<HA$3,GZ4<HA4)), 1, 0)))) | HD4: RUBELIO MEJIA | HE4: 2 | HF4: 2 | HG4: =IF(OR(HE$3="",HF$3="",HE4="",HF4=""), "", IF(AND(HE$3=HE4,HF$3=HF4), 3, IF(AND(HE$3=HF$3,HE4=HF4), 2, IF(OR(AND(HE$3>HF$3,HE4>HF4), AND(HE$3<HF$3,HE4<HF4)), 1, 0)))) | HI4: RUBELIO MEJIA | HJ4: 1 | HK4: 2 | HL4: =IF(OR(HJ$3="",HK$3="",HJ4="",HK4=""), "", IF(AND(HJ$3=HJ4,HK$3=HK4), 3, IF(AND(HJ$3=HK$3,HJ4=HK4), 2, IF(OR(AND(HJ$3>HK$3,HJ4>HK4), AND(HJ$3<HK$3,HJ4<HK4)), 1, 0)))) | HN4: RUBELIO MEJIA | HO4: 4 | HP4: 0 | HQ4: =IF(OR(HO$3="",HP$3="",HO4="",HP4=""), "", IF(AND(HO$3=HO4,HP$3=HP4), 3, IF(AND(HO$3=HP$3,HO4=HP4), 2, IF(OR(AND(HO$3>HP$3,HO4>HP4), AND(HO$3<HP$3,HO4<HP4)), 1, 0)))) | HS4: RUBELIO MEJIA | HT4: 2 | HU4: 1 | HV4: =IF(OR(HT$3="",HU$3="",HT4="",HU4=""), "", IF(AND(HT$3=HT4,HU$3=HU4), 3, IF(AND(HT$3=HU$3,HT4=HU4), 2, IF(OR(AND(HT$3>HU$3,HT4>HU4), AND(HT$3<HU$3,HT4<HU4)), 1, 0)))) | HX4: RUBELIO MEJIA | HY4: 0 | HZ4: 2 | IA4: =IF(OR(HY$3="",HZ$3="",HY4="",HZ4=""), "", IF(AND(HY$3=HY4,HZ$3=HZ4), 3, IF(AND(HY$3=HZ$3,HY4=HZ4), 2, IF(OR(AND(HY$3>HZ$3,HY4>HZ4), AND(HY$3<HZ$3,HY4<HZ4)), 1, 0)))) | IC4: RUBELIO MEJIA | ID4: 2 | IE4: 0 | IF4: =IF(OR(ID$3="",IE$3="",ID4="",IE4=""), "", IF(AND(ID$3=ID4,IE$3=IE4), 3, IF(AND(ID$3=IE$3,ID4=IE4), 2, IF(OR(AND(ID$3>IE$3,ID4>IE4), AND(ID$3<IE$3,ID4<IE4)), 1, 0)))) | IH4: RUBELIO MEJIA | II4: 2 | IJ4: 1 | IK4: =IF(OR(II$3="",IJ$3="",II4="",IJ4=""), "", IF(AND(II$3=II4,IJ$3=IJ4), 3, IF(AND(II$3=IJ$3,II4=IJ4), 2, IF(OR(AND(II$3>IJ$3,II4>IJ4), AND(II$3<IJ$3,II4<IJ4)), 1, 0)))) | IM4: RUBELIO MEJIA | IN4: 2 | IO4: 1 | IP4: =IF(OR(IN$3="",IO$3="",IN4="",IO4=""), "", IF(AND(IN$3=IN4,IO$3=IO4), 3, IF(AND(IN$3=IO$3,IN4=IO4), 2, IF(OR(AND(IN$3>IO$3,IN4>IO4), AND(IN$3<IO$3,IN4<IO4)), 1, 0)))) | IR4: RUBELIO MEJIA | IS4: 3 | IT4: 0 | IU4: =IF(OR(IS$3="",IT$3="",IS4="",IT4=""), "", IF(AND(IS$3=IS4,IT$3=IT4), 3, IF(AND(IS$3=IT$3,IS4=IT4), 2, IF(OR(AND(IS$3>IT$3,IS4>IT4), AND(IS$3<IT$3,IS4<IT4)), 1, 0)))) | IW4: RUBELIO MEJIA | IX4: 0 | IY4: 2 | IZ4: =IF(OR(IX$3="",IY$3="",IX4="",IY4=""), "", IF(AND(IX$3=IX4,IY$3=IY4), 3, IF(AND(IX$3=IY$3,IX4=IY4), 2, IF(OR(AND(IX$3>IY$3,IX4>IY4), AND(IX$3<IY$3,IX4<IY4)), 1, 0)))) | JB4: RUBELIO MEJIA | JC4: 1 | JD4: 2 | JE4: =IF(OR(JC$3="",JD$3="",JC4="",JD4=""), "", IF(AND(JC$3=JC4,JD$3=JD4), 3, IF(AND(JC$3=JD$3,JC4=JD4), 2, IF(OR(AND(JC$3>JD$3,JC4>JD4), AND(JC$3<JD$3,JC4<JD4)), 1, 0)))) | JG4: RUBELIO MEJIA | JH4: 1 | JI4: 1 | JJ4: =IF(OR(JH$3="",JI$3="",JH4="",JI4=""), "", IF(AND(JH$3=JH4,JI$3=JI4), 3, IF(AND(JH$3=JI$3,JH4=JI4), 2, IF(OR(AND(JH$3>JI$3,JH4>JI4), AND(JH$3<JI$3,JH4<JI4)), 1, 0)))) | JL4: RUBELIO MEJIA | JM4: 0 | JN4: 2 | JO4: =IF(OR(JM$3="",JN$3="",JM4="",JN4=""), "", IF(AND(JM$3=JM4,JN$3=JN4), 3, IF(AND(JM$3=JN$3,JM4=JN4), 2, IF(OR(AND(JM$3>JN$3,JM4>JN4), AND(JM$3<JN$3,JM4<JN4)), 1, 0)))) | JQ4: RUBELIO MEJIA | JR4: 1 | JS4: 3 | JT4: =IF(OR(JR$3="",JS$3="",JR4="",JS4=""), "", IF(AND(JR$3=JR4,JS$3=JS4), 3, IF(AND(JR$3=JS$3,JR4=JS4), 2, IF(OR(AND(JR$3>JS$3,JR4>JS4), AND(JR$3<JS$3,JR4<JS4)), 1, 0)))) | JV4: RUBELIO MEJIA | JW4: 1 | JX4: 2 | JY4: =IF(OR(JW$3="",JX$3="",JW4="",JX4=""), "", IF(AND(JW$3=JW4,JX$3=JX4), 3, IF(AND(JW$3=JX$3,JW4=JX4), 2, IF(OR(AND(JW$3>JX$3,JW4>JX4), AND(JW$3<JX$3,JW4<JX4)), 1, 0)))) | KA4: RUBELIO MEJIA | KB4: 1 | KC4: 1 | KD4: =IF(OR(KB$3="",KC$3="",KB4="",KC4=""), "", IF(AND(KB$3=KB4,KC$3=KC4), 3, IF(AND(KB$3=KC$3,KB4=KC4), 2, IF(OR(AND(KB$3>KC$3,KB4>KC4), AND(KB$3<KC$3,KB4<KC4)), 1, 0)))) | KF4: RUBELIO MEJIA | KG4: 1 | KH4: 1 | KI4: =IF(OR(KG$3="",KH$3="",KG4="",KH4=""), "", IF(AND(KG$3=KG4,KH$3=KH4), 3, IF(AND(KG$3=KH$3,KG4=KH4), 2, IF(OR(AND(KG$3>KH$3,KG4>KH4), AND(KG$3<KH$3,KG4<KH4)), 1, 0)))) | KK4: RUBELIO MEJIA | KL4: 2 | KM4: 0 | KN4: =IF(OR(KL$3="",KM$3="",KL4="",KM4=""), "", IF(AND(KL$3=KL4,KM$3=KM4), 3, IF(AND(KL$3=KM$3,KL4=KM4), 2, IF(OR(AND(KL$3>KM$3,KL4>KM4), AND(KL$3<KM$3,KL4<KM4)), 1, 0)))) | KP4: RUBELIO MEJIA | KQ4: 1 | KR4: 3 | KS4: =IF(OR(KQ$3="",KR$3="",KQ4="",KR4=""), "", IF(AND(KQ$3=KQ4,KR$3=KR4), 3, IF(AND(KQ$3=KR$3,KQ4=KR4), 2, IF(OR(AND(KQ$3>KR$3,KQ4>KR4), AND(KQ$3<KR$3,KQ4<KR4)), 1, 0)))) | KU4: RUBELIO MEJIA | KV4: 2 | KW4: 1 | KX4: =IF(OR(KV$3="",KW$3="",KV4="",KW4=""), "", IF(AND(KV$3=KV4,KW$3=KW4), 3, IF(AND(KV$3=KW$3,KV4=KW4), 2, IF(OR(AND(KV$3>KW$3,KV4>KW4), AND(KV$3<KW$3,KV4<KW4)), 1, 0)))) | KZ4: RUBELIO MEJIA | LA4: 1 | LB4: 1 | LC4: =IF(OR(LA$3="",LB$3="",LA4="",LB4=""), "", IF(AND(LA$3=LA4,LB$3=LB4), 3, IF(AND(LA$3=LB$3,LA4=LB4), 2, IF(OR(AND(LA$3>LB$3,LA4>LB4), AND(LA$3<LB$3,LA4<LB4)), 1, 0)))) | LE4: RUBELIO MEJIA | LF4: 1 | LG4: 2 | LH4: =IF(OR(LF$3="",LG$3="",LF4="",LG4=""), "", IF(AND(LF$3=LF4,LG$3=LG4), 3, IF(AND(LF$3=LG$3,LF4=LG4), 2, IF(OR(AND(LF$3>LG$3,LF4>LG4), AND(LF$3<LG$3,LF4<LG4)), 1, 0)))) | LJ4: RUBELIO MEJIA | LK4: 0 | LL4: 3 | LM4: =IF(OR(LK$3="",LL$3="",LK4="",LL4=""), "", IF(AND(LK$3=LK4,LL$3=LL4), 3, IF(AND(LK$3=LL$3,LK4=LL4), 2, IF(OR(AND(LK$3>LL$3,LK4>LL4), AND(LK$3<LL$3,LK4<LL4)), 1, 0)))) | LO4: RUBELIO MEJIA | LP4: 2 | LQ4: 2 | LR4: =IF(OR(LP$3="",LQ$3="",LP4="",LQ4=""), "", IF(AND(LP$3=LP4,LQ$3=LQ4), 3, IF(AND(LP$3=LQ$3,LP4=LQ4), 2, IF(OR(AND(LP$3>LQ$3,LP4>LQ4), AND(LP$3<LQ$3,LP4<LQ4)), 1, 0)))) | LT4: RUBELIO MEJIA | LU4: 0 | LV4: 3 | LW4: =IF(OR(LU$3="",LV$3="",LU4="",LV4=""), "", IF(AND(LU$3=LU4,LV$3=LV4), 3, IF(AND(LU$3=LV$3,LU4=LV4), 2, IF(OR(AND(LU$3>LV$3,LU4>LV4), AND(LU$3<LV$3,LU4<LV4)), 1, 0)))) | LY4: RUBELIO MEJIA | LZ4: 2 | MA4: 2 | MB4: =IF(OR(LZ$3="",MA$3="",LZ4="",MA4=""), "", IF(AND(LZ$3=LZ4,MA$3=MA4), 3, IF(AND(LZ$3=MA$3,LZ4=MA4), 2, IF(OR(AND(LZ$3>MA$3,LZ4>MA4), AND(LZ$3<MA$3,LZ4<MA4)), 1, 0)))) | MD4: RUBELIO MEJIA | ME4: 2 | MF4: 1 | MG4: =IF(OR(ME$3="",MF$3="",ME4="",MF4=""), "", IF(AND(ME$3=ME4,MF$3=MF4), 3, IF(AND(ME$3=MF$3,ME4=MF4), 2, IF(OR(AND(ME$3>MF$3,ME4>MF4), AND(ME$3<MF$3,ME4<MF4)), 1, 0)))) | MI4: RUBELIO MEJIA | MJ4: 2 | MK4: 1 | ML4: =IF(OR(MJ$3="",MK$3="",MJ4="",MK4=""), "", IF(AND(MJ$3=MJ4,MK$3=MK4), 3, IF(AND(MJ$3=MK$3,MJ4=MK4), 2, IF(OR(AND(MJ$3>MK$3,MJ4>MK4), AND(MJ$3<MK$3,MJ4<MK4)), 1, 0)))) | MN4: RUBELIO MEJIA | MO4: 1 | MP4: 2 | MQ4: =IF(OR(MO$3="",MP$3="",MO4="",MP4=""), "", IF(AND(MO$3=MO4,MP$3=MP4), 3, IF(AND(MO$3=MP$3,MO4=MP4), 2, IF(OR(AND(MO$3>MP$3,MO4>MP4), AND(MO$3<MP$3,MO4<MP4)), 1, 0)))) | MS4: RUBELIO MEJIA | MT4: 0 | MU4: 3 | MV4: =IF(OR(MT$3="",MU$3="",MT4="",MU4=""), "", IF(AND(MT$3=MT4,MU$3=MU4), 3, IF(AND(MT$3=MU$3,MT4=MU4), 2, IF(OR(AND(MT$3>MU$3,MT4>MU4), AND(MT$3<MU$3,MT4<MU4)), 1, 0)))) | MX4: RUBELIO MEJIA | MY4: FRANCIA | NA4: BRASIL | NC4: ESPAÑA | NE4: COLOMBIA | NG4: MICHAEL OLISSE | NI4: =SUM(E4,J4,O4,T4,Y4,AD4,AI4,AN4,AS4,AX4,BC4,BH4,BM4,BR4,,BW4,CB4,CG4,CL4,CQ4,CV4,DA4,DF4,DK4,DP4,DU4,DZ4,EE4,EJ4,EO4,ET4,EY4,FD4,FI4,FN4,FS4,FX4,GC4,GH4,GM4,GR4,GW4,HB4,HG4,HL4,HQ4,HV4,IA4,IF4,IK4,IP4,IU4,IZ4,JE4,JJ4,JO4,JT4,JY4,KD4,KI4,KN4,KS4,KX4,LC4,LH4,LM4,LR4,LW4,MB4,MG4,ML4,MQ4,MV4,MZ4,NB4,ND4,NF4,NH4,) -> 4
A5: 2 | B5: PABLO CARDENAS | C5: 2 | D5: 0 | E5: =IF(OR(C$3="",D$3="",C5="",D5=""), "", IF(AND(C$3=C5,D$3=D5), 3, IF(AND(C$3=D$3,C5=D5), 2, IF(OR(AND(C$3>D$3,C5>D5), AND(C$3<D$3,C5<D5)), 1, 0)))) -> 3 | G5: PABLO CARDENAS | H5: 2 | I5: 2 | J5: =IF(OR(H$3="",I$3="",H5="",I5=""), "", IF(AND(H$3=H5,I$3=I5), 3, IF(AND(H$3=I$3,H5=I5), 2, IF(OR(AND(H$3>I$3,H5>I5), AND(H$3<I$3,H5<I5)), 1, 0)))) -> 0 | L5: PABLO CARDENAS | M5: 1 | N5: 1 | O5: =IF(OR(M$3="",N$3="",M5="",N5=""), "", IF(AND(M$3=M5,N$3=N5), 3, IF(AND(M$3=N$3,M5=N5), 2, IF(OR(AND(M$3>N$3,M5>N5), AND(M$3<N$3,M5<N5)), 1, 0)))) -> 3 | Q5: PABLO CARDENAS | R5: 2 | S5: 1 | T5: =IF(OR(R$3="",S$3="",R5="",S5=""), "", IF(AND(R$3=R5,S$3=S5), 3, IF(AND(R$3=S$3,R5=S5), 2, IF(OR(AND(R$3>S$3,R5>S5), AND(R$3<S$3,R5<S5)), 1, 0)))) -> 1 | V5: PABLO CARDENAS | W5: 0 | X5: 3 | Y5: =IF(OR(W$3="",X$3="",W5="",X5=""), "", IF(AND(W$3=W5,X$3=X5), 3, IF(AND(W$3=X$3,W5=X5), 2, IF(OR(AND(W$3>X$3,W5>X5), AND(W$3<X$3,W5<X5)), 1, 0)))) -> 0 | AA5: PABLO CARDENAS | AB5: 3 | AC5: 1 | AD5: =IF(OR(AB$3="",AC$3="",AB5="",AC5=""), "", IF(AND(AB$3=AB5,AC$3=AC5), 3, IF(AND(AB$3=AC$3,AB5=AC5), 2, IF(OR(AND(AB$3>AC$3,AB5>AC5), AND(AB$3<AC$3,AB5<AC5)), 1, 0)))) -> 0 | AF5: PABLO CARDENAS | AG5: 0 | AH5: 3 | AI5: =IF(OR(AG$3="",AH$3="",AG5="",AH5=""), "", IF(AND(AG$3=AG5,AH$3=AH5), 3, IF(AND(AG$3=AH$3,AG5=AH5), 2, IF(OR(AND(AG$3>AH$3,AG5>AH5), AND(AG$3<AH$3,AG5<AH5)), 1, 0)))) | AK5: PABLO CARDENAS | AL5: 1 | AM5: 2 | AN5: =IF(OR(AL$3="",AM$3="",AL5="",AM5=""), "", IF(AND(AL$3=AL5,AM$3=AM5), 3, IF(AND(AL$3=AM$3,AL5=AM5), 2, IF(OR(AND(AL$3>AM$3,AL5>AM5), AND(AL$3<AM$3,AL5<AM5)), 1, 0)))) | AP5: PABLO CARDENAS | AQ5: 4 | AR5: 0 | AS5: =IF(OR(AQ$3="",AR$3="",AQ5="",AR5=""), "", IF(AND(AQ$3=AQ5,AR$3=AR5), 3, IF(AND(AQ$3=AR$3,AQ5=AR5), 2, IF(OR(AND(AQ$3>AR$3,AQ5>AR5), AND(AQ$3<AR$3,AQ5<AR5)), 1, 0)))) | AU5: PABLO CARDENAS | AV5: 3 | AW5: 1 | AX5: =IF(OR(AV$3="",AW$3="",AV5="",AW5=""), "", IF(AND(AV$3=AV5,AW$3=AW5), 3, IF(AND(AV$3=AW$3,AV5=AW5), 2, IF(OR(AND(AV$3>AW$3,AV5>AW5), AND(AV$3<AW$3,AV5<AW5)), 1, 0)))) | AZ5: PABLO CARDENAS | BA5: 2 | BB5: 2 | BC5: =IF(OR(BA$3="",BB$3="",BA5="",BB5=""), "", IF(AND(BA$3=BA5,BB$3=BB5), 3, IF(AND(BA$3=BB$3,BA5=BB5), 2, IF(OR(AND(BA$3>BB$3,BA5>BB5), AND(BA$3<BB$3,BA5<BB5)), 1, 0)))) | BE5: PABLO CARDENAS | BF5: 2 | BG5: 0 | BH5: =IF(OR(BF$3="",BG$3="",BF5="",BG5=""), "", IF(AND(BF$3=BF5,BG$3=BG5), 3, IF(AND(BF$3=BG$3,BF5=BG5), 2, IF(OR(AND(BF$3>BG$3,BF5>BG5), AND(BF$3<BG$3,BF5<BG5)), 1, 0)))) | BJ5: PABLO CARDENAS | BK5: 5 | BL5: 0 | BM5: =IF(OR(BK$3="",BL$3="",BK5="",BL5=""), "", IF(AND(BK$3=BK5,BL$3=BL5), 3, IF(AND(BK$3=BL$3,BK5=BL5), 2, IF(OR(AND(BK$3>BL$3,BK5>BL5), AND(BK$3<BL$3,BK5<BL5)), 1, 0)))) | BO5: PABLO CARDENAS | BP5: 2 | BQ5: 1 | BR5: =IF(OR(BP$3="",BQ$3="",BP5="",BQ5=""), "", IF(AND(BP$3=BP5,BQ$3=BQ5), 3, IF(AND(BP$3=BQ$3,BP5=BQ5), 2, IF(OR(AND(BP$3>BQ$3,BP5>BQ5), AND(BP$3<BQ$3,BP5<BQ5)), 1, 0)))) | BT5: PABLO CARDENAS | BU5: 0 | BV5: 2 | BW5: =IF(OR(BU$3="",BV$3="",BU5="",BV5=""), "", IF(AND(BU$3=BU5,BV$3=BV5), 3, IF(AND(BU$3=BV$3,BU5=BV5), 2, IF(OR(AND(BU$3>BV$3,BU5>BV5), AND(BU$3<BV$3,BU5<BV5)), 1, 0)))) | BY5: PABLO CARDENAS | BZ5: 1 | CA5: 1 | CB5: =IF(OR(BZ$3="",CA$3="",BZ5="",CA5=""), "", IF(AND(BZ$3=BZ5,CA$3=CA5), 3, IF(AND(BZ$3=CA$3,BZ5=CA5), 2, IF(OR(AND(BZ$3>CA$3,BZ5>CA5), AND(BZ$3<CA$3,BZ5<CA5)), 1, 0)))) | CD5: PABLO CARDENAS | CE5: 3 | CF5: 0 | CG5: =IF(OR(CE$3="",CF$3="",CE5="",CF5=""), "", IF(AND(CE$3=CE5,CF$3=CF5), 3, IF(AND(CE$3=CF$3,CE5=CF5), 2, IF(OR(AND(CE$3>CF$3,CE5>CF5), AND(CE$3<CF$3,CE5<CF5)), 1, 0)))) | CI5: PABLO CARDENAS | CJ5: 0 | CK5: 2 | CL5: =IF(OR(CJ$3="",CK$3="",CJ5="",CK5=""), "", IF(AND(CJ$3=CJ5,CK$3=CK5), 3, IF(AND(CJ$3=CK$3,CJ5=CK5), 2, IF(OR(AND(CJ$3>CK$3,CJ5>CK5), AND(CJ$3<CK$3,CJ5<CK5)), 1, 0)))) | CN5: PABLO CARDENAS | CO5: 2 | CP5: 0 | CQ5: =IF(OR(CO$3="",CP$3="",CO5="",CP5=""), "", IF(AND(CO$3=CO5,CP$3=CP5), 3, IF(AND(CO$3=CP$3,CO5=CP5), 2, IF(OR(AND(CO$3>CP$3,CO5>CP5), AND(CO$3<CP$3,CO5<CP5)), 1, 0)))) | CS5: PABLO CARDENAS | CT5: 2 | CU5: 0 | CV5: =IF(OR(CT$3="",CU$3="",CT5="",CU5=""), "", IF(AND(CT$3=CT5,CU$3=CU5), 3, IF(AND(CT$3=CU$3,CT5=CU5), 2, IF(OR(AND(CT$3>CU$3,CT5>CU5), AND(CT$3<CU$3,CT5<CU5)), 1, 0)))) | CX5: PABLO CARDENAS | CY5: 3 | CZ5: 0 | DA5: =IF(OR(CY$3="",CZ$3="",CY5="",CZ5=""), "", IF(AND(CY$3=CY5,CZ$3=CZ5), 3, IF(AND(CY$3=CZ$3,CY5=CZ5), 2, IF(OR(AND(CY$3>CZ$3,CY5>CZ5), AND(CY$3<CZ$3,CY5<CZ5)), 1, 0)))) | DC5: PABLO CARDENAS | DD5: 2 | DE5: 1 | DF5: =IF(OR(DD$3="",DE$3="",DD5="",DE5=""), "", IF(AND(DD$3=DD5,DE$3=DE5), 3, IF(AND(DD$3=DE$3,DD5=DE5), 2, IF(OR(AND(DD$3>DE$3,DD5>DE5), AND(DD$3<DE$3,DD5<DE5)), 1, 0)))) | DH5: PABLO CARDENAS | DI5: 1 | DJ5: 1 | DK5: =IF(OR(DI$3="",DJ$3="",DI5="",DJ5=""), "", IF(AND(DI$3=DI5,DJ$3=DJ5), 3, IF(AND(DI$3=DJ$3,DI5=DJ5), 2, IF(OR(AND(DI$3>DJ$3,DI5>DJ5), AND(DI$3<DJ$3,DI5<DJ5)), 1, 0)))) | DM5: PABLO CARDENAS | DN5: 1 | DO5: 2 | DP5: =IF(OR(DN$3="",DO$3="",DN5="",DO5=""), "", IF(AND(DN$3=DN5,DO$3=DO5), 3, IF(AND(DN$3=DO$3,DN5=DO5), 2, IF(OR(AND(DN$3>DO$3,DN5>DO5), AND(DN$3<DO$3,DN5<DO5)), 1, 0)))) | DR5: PABLO CARDENAS | DS5: 1 | DT5: 0 | DU5: =IF(OR(DS$3="",DT$3="",DS5="",DT5=""), "", IF(AND(DS$3=DS5,DT$3=DT5), 3, IF(AND(DS$3=DT$3,DS5=DT5), 2, IF(OR(AND(DS$3>DT$3,DS5>DT5), AND(DS$3<DT$3,DS5<DT5)), 1, 0)))) | DW5: PABLO CARDENAS | DX5: 2 | DY5: 0 | DZ5: =IF(OR(DX$3="",DY$3="",DX5="",DY5=""), "", IF(AND(DX$3=DX5,DY$3=DY5), 3, IF(AND(DX$3=DY$3,DX5=DY5), 2, IF(OR(AND(DX$3>DY$3,DX5>DY5), AND(DX$3<DY$3,DX5<DY5)), 1, 0)))) | EB5: PABLO CARDENAS | EC5: 1 | ED5: 1 | EE5: =IF(OR(EC$3="",ED$3="",EC5="",ED5=""), "", IF(AND(EC$3=EC5,ED$3=ED5), 3, IF(AND(EC$3=ED$3,EC5=ED5), 2, IF(OR(AND(EC$3>ED$3,EC5>ED5), AND(EC$3<ED$3,EC5<ED5)), 1, 0)))) | EG5: PABLO CARDENAS | EH5: 1 | EI5: 1 | EJ5: =IF(OR(EH$3="",EI$3="",EH5="",EI5=""), "", IF(AND(EH$3=EH5,EI$3=EI5), 3, IF(AND(EH$3=EI$3,EH5=EI5), 2, IF(OR(AND(EH$3>EI$3,EH5>EI5), AND(EH$3<EI$3,EH5<EI5)), 1, 0)))) | EL5: PABLO CARDENAS | EM5: 2 | EN5: 1 | EO5: =IF(OR(EM$3="",EN$3="",EM5="",EN5=""), "", IF(AND(EM$3=EM5,EN$3=EN5), 3, IF(AND(EM$3=EN$3,EM5=EN5), 2, IF(OR(AND(EM$3>EN$3,EM5>EN5), AND(EM$3<EN$3,EM5<EN5)), 1, 0)))) | EQ5: PABLO CARDENAS | ER5: 1 | ES5: 1 | ET5: =IF(OR(ER$3="",ES$3="",ER5="",ES5=""), "", IF(AND(ER$3=ER5,ES$3=ES5), 3, IF(AND(ER$3=ES$3,ER5=ES5), 2, IF(OR(AND(ER$3>ES$3,ER5>ES5), AND(ER$3<ES$3,ER5<ES5)), 1, 0)))) | EV5: PABLO CARDENAS | EW5: 3 | EX5: 0 | EY5: =IF(OR(EW$3="",EX$3="",EW5="",EX5=""), "", IF(AND(EW$3=EW5,EX$3=EX5), 3, IF(AND(EW$3=EX$3,EW5=EX5), 2, IF(OR(AND(EW$3>EX$3,EW5>EX5), AND(EW$3<EX$3,EW5<EX5)), 1, 0)))) | FA5: PABLO CARDENAS | FB5: 2 | FC5: 2 | FD5: =IF(OR(FB$3="",FC$3="",FB5="",FC5=""), "", IF(AND(FB$3=FB5,FC$3=FC5), 3, IF(AND(FB$3=FC$3,FB5=FC5), 2, IF(OR(AND(FB$3>FC$3,FB5>FC5), AND(FB$3<FC$3,FB5<FC5)), 1, 0)))) | FF5: PABLO CARDENAS | FG5: 2 | FH5: 1 | FI5: =IF(OR(FG$3="",FH$3="",FG5="",FH5=""), "", IF(AND(FG$3=FG5,FH$3=FH5), 3, IF(AND(FG$3=FH$3,FG5=FH5), 2, IF(OR(AND(FG$3>FH$3,FG5>FH5), AND(FG$3<FH$3,FG5<FH5)), 1, 0)))) | FK5: PABLO CARDENAS | FL5: 2 | FM5: 0 | FN5: =IF(OR(FL$3="",FM$3="",FL5="",FM5=""), "", IF(AND(FL$3=FL5,FM$3=FM5), 3, IF(AND(FL$3=FM$3,FL5=FM5), 2, IF(OR(AND(FL$3>FM$3,FL5>FM5), AND(FL$3<FM$3,FL5<FM5)), 1, 0)))) | FP5: PABLO CARDENAS | FQ5: 2 | FR5: 0 | FS5: =IF(OR(FQ$3="",FR$3="",FQ5="",FR5=""), "", IF(AND(FQ$3=FQ5,FR$3=FR5), 3, IF(AND(FQ$3=FR$3,FQ5=FR5), 2, IF(OR(AND(FQ$3>FR$3,FQ5>FR5), AND(FQ$3<FR$3,FQ5<FR5)), 1, 0)))) | FU5: PABLO CARDENAS | FV5: 1 | FW5: 2 | FX5: =IF(OR(FV$3="",FW$3="",FV5="",FW5=""), "", IF(AND(FV$3=FV5,FW$3=FW5), 3, IF(AND(FV$3=FW$3,FV5=FW5), 2, IF(OR(AND(FV$3>FW$3,FV5>FW5), AND(FV$3<FW$3,FV5<FW5)), 1, 0)))) | FZ5: PABLO CARDENAS | GA5: 3 | GB5: 0 | GC5: =IF(OR(GA$3="",GB$3="",GA5="",GB5=""), "", IF(AND(GA$3=GA5,GB$3=GB5), 3, IF(AND(GA$3=GB$3,GA5=GB5), 2, IF(OR(AND(GA$3>GB$3,GA5>GB5), AND(GA$3<GB$3,GA5<GB5)), 1, 0)))) | GE5: PABLO CARDENAS | GF5: 3 | GG5: 0 | GH5: =IF(OR(GF$3="",GG$3="",GF5="",GG5=""), "", IF(AND(GF$3=GF5,GG$3=GG5), 3, IF(AND(GF$3=GG$3,GF5=GG5), 2, IF(OR(AND(GF$3>GG$3,GF5>GG5), AND(GF$3<GG$3,GF5<GG5)), 1, 0)))) | GJ5: PABLO CARDENAS | GK5: 2 | GL5: 0 | GM5: =IF(OR(GK$3="",GL$3="",GK5="",GL5=""), "", IF(AND(GK$3=GK5,GL$3=GL5), 3, IF(AND(GK$3=GL$3,GK5=GL5), 2, IF(OR(AND(GK$3>GL$3,GK5>GL5), AND(GK$3<GL$3,GK5<GL5)), 1, 0)))) | GO5: PABLO CARDENAS | GP5: 0 | GQ5: 1 | GR5: =IF(OR(GP$3="",GQ$3="",GP5="",GQ5=""), "", IF(AND(GP$3=GP5,GQ$3=GQ5), 3, IF(AND(GP$3=GQ$3,GP5=GQ5), 2, IF(OR(AND(GP$3>GQ$3,GP5>GQ5), AND(GP$3<GQ$3,GP5<GQ5)), 1, 0)))) | GT5: PABLO CARDENAS | GU5: 1 | GV5: 1 | GW5: =IF(OR(GU$3="",GV$3="",GU5="",GV5=""), "", IF(AND(GU$3=GU5,GV$3=GV5), 3, IF(AND(GU$3=GV$3,GU5=GV5), 2, IF(OR(AND(GU$3>GV$3,GU5>GV5), AND(GU$3<GV$3,GU5<GV5)), 1, 0)))) | GY5: PABLO CARDENAS | GZ5: 2 | HA5: O | HB5: =IF(OR(GZ$3="",HA$3="",GZ5="",HA5=""), "", IF(AND(GZ$3=GZ5,HA$3=HA5), 3, IF(AND(GZ$3=HA$3,GZ5=HA5), 2, IF(OR(AND(GZ$3>HA$3,GZ5>HA5), AND(GZ$3<HA$3,GZ5<HA5)), 1, 0)))) | HD5: PABLO CARDENAS | HE5: 2 | HF5: 0 | HG5: =IF(OR(HE$3="",HF$3="",HE5="",HF5=""), "", IF(AND(HE$3=HE5,HF$3=HF5), 3, IF(AND(HE$3=HF$3,HE5=HF5), 2, IF(OR(AND(HE$3>HF$3,HE5>HF5), AND(HE$3<HF$3,HE5<HF5)), 1, 0)))) | HI5: PABLO CARDENAS | HJ5: 1 | HK5: 2 | HL5: =IF(OR(HJ$3="",HK$3="",HJ5="",HK5=""), "", IF(AND(HJ$3=HJ5,HK$3=HK5), 3, IF(AND(HJ$3=HK$3,HJ5=HK5), 2, IF(OR(AND(HJ$3>HK$3,HJ5>HK5), AND(HJ$3<HK$3,HJ5<HK5)), 1, 0)))) | HN5: PABLO CARDENAS | HO5: 2 | HP5: 0 | HQ5: =IF(OR(HO$3="",HP$3="",HO5="",HP5=""), "", IF(AND(HO$3=HO5,HP$3=HP5), 3, IF(AND(HO$3=HP$3,HO5=HP5), 2, IF(OR(AND(HO$3>HP$3,HO5>HP5), AND(HO$3<HP$3,HO5<HP5)), 1, 0)))) | HS5: PABLO CARDENAS | HT5: 2 | HU5: 0 | HV5: =IF(OR(HT$3="",HU$3="",HT5="",HU5=""), "", IF(AND(HT$3=HT5,HU$3=HU5), 3, IF(AND(HT$3=HU$3,HT5=HU5), 2, IF(OR(AND(HT$3>HU$3,HT5>HU5), AND(HT$3<HU$3,HT5<HU5)), 1, 0)))) | HX5: PABLO CARDENAS | HY5: 1 | HZ5: 2 | IA5: =IF(OR(HY$3="",HZ$3="",HY5="",HZ5=""), "", IF(AND(HY$3=HY5,HZ$3=HZ5), 3, IF(AND(HY$3=HZ$3,HY5=HZ5), 2, IF(OR(AND(HY$3>HZ$3,HY5>HZ5), AND(HY$3<HZ$3,HY5<HZ5)), 1, 0)))) | IC5: PABLO CARDENAS | ID5: 2 | IE5: 0 | IF5: =IF(OR(ID$3="",IE$3="",ID5="",IE5=""), "", IF(AND(ID$3=ID5,IE$3=IE5), 3, IF(AND(ID$3=IE$3,ID5=IE5), 2, IF(OR(AND(ID$3>IE$3,ID5>IE5), AND(ID$3<IE$3,ID5<IE5)), 1, 0)))) | IH5: PABLO CARDENAS | II5: 1 | IJ5: 0 | IK5: =IF(OR(II$3="",IJ$3="",II5="",IJ5=""), "", IF(AND(II$3=II5,IJ$3=IJ5), 3, IF(AND(II$3=IJ$3,II5=IJ5), 2, IF(OR(AND(II$3>IJ$3,II5>IJ5), AND(II$3<IJ$3,II5<IJ5)), 1, 0)))) | IM5: PABLO CARDENAS | IN5: 1 | IO5: 0 | IP5: =IF(OR(IN$3="",IO$3="",IN5="",IO5=""), "", IF(AND(IN$3=IN5,IO$3=IO5), 3, IF(AND(IN$3=IO$3,IN5=IO5), 2, IF(OR(AND(IN$3>IO$3,IN5>IO5), AND(IN$3<IO$3,IN5<IO5)), 1, 0)))) | IR5: PABLO CARDENAS | IS5: 2 | IT5: 0 | IU5: =IF(OR(IS$3="",IT$3="",IS5="",IT5=""), "", IF(AND(IS$3=IS5,IT$3=IT5), 3, IF(AND(IS$3=IT$3,IS5=IT5), 2, IF(OR(AND(IS$3>IT$3,IS5>IT5), AND(IS$3<IT$3,IS5<IT5)), 1, 0)))) | IW5: PABLO CARDENAS | IX5: 1 | IY5: 2 | IZ5: =IF(OR(IX$3="",IY$3="",IX5="",IY5=""), "", IF(AND(IX$3=IX5,IY$3=IY5), 3, IF(AND(IX$3=IY$3,IX5=IY5), 2, IF(OR(AND(IX$3>IY$3,IX5>IY5), AND(IX$3<IY$3,IX5<IY5)), 1, 0)))) | JB5: PABLO CARDENAS | JC5: 1 | JD5: 2 | JE5: =IF(OR(JC$3="",JD$3="",JC5="",JD5=""), "", IF(AND(JC$3=JC5,JD$3=JD5), 3, IF(AND(JC$3=JD$3,JC5=JD5), 2, IF(OR(AND(JC$3>JD$3,JC5>JD5), AND(JC$3<JD$3,JC5<JD5)), 1, 0)))) | JG5: PABLO CARDENAS | JH5: 2 | JI5: 2 | JJ5: =IF(OR(JH$3="",JI$3="",JH5="",JI5=""), "", IF(AND(JH$3=JH5,JI$3=JI5), 3, IF(AND(JH$3=JI$3,JH5=JI5), 2, IF(OR(AND(JH$3>JI$3,JH5>JI5), AND(JH$3<JI$3,JH5<JI5)), 1, 0)))) | JL5: PABLO CARDENAS | JM5: 0 | JN5: 2 | JO5: =IF(OR(JM$3="",JN$3="",JM5="",JN5=""), "", IF(AND(JM$3=JM5,JN$3=JN5), 3, IF(AND(JM$3=JN$3,JM5=JN5), 2, IF(OR(AND(JM$3>JN$3,JM5>JN5), AND(JM$3<JN$3,JM5<JN5)), 1, 0)))) | JQ5: PABLO CARDENAS | JR5: 1 | JS5: 2 | JT5: =IF(OR(JR$3="",JS$3="",JR5="",JS5=""), "", IF(AND(JR$3=JR5,JS$3=JS5), 3, IF(AND(JR$3=JS$3,JR5=JS5), 2, IF(OR(AND(JR$3>JS$3,JR5>JS5), AND(JR$3<JS$3,JR5<JS5)), 1, 0)))) | JV5: PABLO CARDENAS | JW5: 0 | JX5: 3 | JY5: =IF(OR(JW$3="",JX$3="",JW5="",JX5=""), "", IF(AND(JW$3=JW5,JX$3=JX5), 3, IF(AND(JW$3=JX$3,JW5=JX5), 2, IF(OR(AND(JW$3>JX$3,JW5>JX5), AND(JW$3<JX$3,JW5<JX5)), 1, 0)))) | KA5: PABLO CARDENAS | KB5: 1 | KC5: 1 | KD5: =IF(OR(KB$3="",KC$3="",KB5="",KC5=""), "", IF(AND(KB$3=KB5,KC$3=KC5), 3, IF(AND(KB$3=KC$3,KB5=KC5), 2, IF(OR(AND(KB$3>KC$3,KB5>KC5), AND(KB$3<KC$3,KB5<KC5)), 1, 0)))) | KF5: PABLO CARDENAS | KG5: 1 | KH5: 1 | KI5: =IF(OR(KG$3="",KH$3="",KG5="",KH5=""), "", IF(AND(KG$3=KG5,KH$3=KH5), 3, IF(AND(KG$3=KH$3,KG5=KH5), 2, IF(OR(AND(KG$3>KH$3,KG5>KH5), AND(KG$3<KH$3,KG5<KH5)), 1, 0)))) | KK5: PABLO CARDENAS | KL5: 1 | KM5: 0 | KN5: =IF(OR(KL$3="",KM$3="",KL5="",KM5=""), "", IF(AND(KL$3=KL5,KM$3=KM5), 3, IF(AND(KL$3=KM$3,KL5=KM5), 2, IF(OR(AND(KL$3>KM$3,KL5>KM5), AND(KL$3<KM$3,KL5<KM5)), 1, 0)))) | KP5: PABLO CARDENAS | KQ5: 1 | KR5: 1 | KS5: =IF(OR(KQ$3="",KR$3="",KQ5="",KR5=""), "", IF(AND(KQ$3=KQ5,KR$3=KR5), 3, IF(AND(KQ$3=KR$3,KQ5=KR5), 2, IF(OR(AND(KQ$3>KR$3,KQ5>KR5), AND(KQ$3<KR$3,KQ5<KR5)), 1, 0)))) | KU5: PABLO CARDENAS | KV5: 2 | KW5: 2 | KX5: =IF(OR(KV$3="",KW$3="",KV5="",KW5=""), "", IF(AND(KV$3=KV5,KW$3=KW5), 3, IF(AND(KV$3=KW$3,KV5=KW5), 2, IF(OR(AND(KV$3>KW$3,KV5>KW5), AND(KV$3<KW$3,KV5<KW5)), 1, 0)))) | KZ5: PABLO CARDENAS | LA5: 0 | LB5: 2 | LC5: =IF(OR(LA$3="",LB$3="",LA5="",LB5=""), "", IF(AND(LA$3=LA5,LB$3=LB5), 3, IF(AND(LA$3=LB$3,LA5=LB5), 2, IF(OR(AND(LA$3>LB$3,LA5>LB5), AND(LA$3<LB$3,LA5<LB5)), 1, 0)))) | LE5: PABLO CARDENAS | LF5: 1 | LG5: 2 | LH5: =IF(OR(LF$3="",LG$3="",LF5="",LG5=""), "", IF(AND(LF$3=LF5,LG$3=LG5), 3, IF(AND(LF$3=LG$3,LF5=LG5), 2, IF(OR(AND(LF$3>LG$3,LF5>LG5), AND(LF$3<LG$3,LF5<LG5)), 1, 0)))) | LJ5: PABLO CARDENAS | LK5: 0 | LL5: 2 | LM5: =IF(OR(LK$3="",LL$3="",LK5="",LL5=""), "", IF(AND(LK$3=LK5,LL$3=LL5), 3, IF(AND(LK$3=LL$3,LK5=LL5), 2, IF(OR(AND(LK$3>LL$3,LK5>LL5), AND(LK$3<LL$3,LK5<LL5)), 1, 0)))) | LO5: PABLO CARDENAS | LP5: 1 | LQ5: 0 | LR5: =IF(OR(LP$3="",LQ$3="",LP5="",LQ5=""), "", IF(AND(LP$3=LP5,LQ$3=LQ5), 3, IF(AND(LP$3=LQ$3,LP5=LQ5), 2, IF(OR(AND(LP$3>LQ$3,LP5>LQ5), AND(LP$3<LQ$3,LP5<LQ5)), 1, 0)))) | LT5: PABLO CARDENAS | LU5: 0 | LV5: 3 | LW5: =IF(OR(LU$3="",LV$3="",LU5="",LV5=""), "", IF(AND(LU$3=LU5,LV$3=LV5), 3, IF(AND(LU$3=LV$3,LU5=LV5), 2, IF(OR(AND(LU$3>LV$3,LU5>LV5), AND(LU$3<LV$3,LU5<LV5)), 1, 0)))) | LY5: PABLO CARDENAS | LZ5: 2 | MA5: 1 | MB5: =IF(OR(LZ$3="",MA$3="",LZ5="",MA5=""), "", IF(AND(LZ$3=LZ5,MA$3=MA5), 3, IF(AND(LZ$3=MA$3,LZ5=MA5), 2, IF(OR(AND(LZ$3>MA$3,LZ5>MA5), AND(LZ$3<MA$3,LZ5<MA5)), 1, 0)))) | MD5: PABLO CARDENAS | ME5: 1 | MF5: 1 | MG5: =IF(OR(ME$3="",MF$3="",ME5="",MF5=""), "", IF(AND(ME$3=ME5,MF$3=MF5), 3, IF(AND(ME$3=MF$3,ME5=MF5), 2, IF(OR(AND(ME$3>MF$3,ME5>MF5), AND(ME$3<MF$3,ME5<MF5)), 1, 0)))) | MI5: PABLO CARDENAS | MJ5: 0 | MK5: 1 | ML5: =IF(OR(MJ$3="",MK$3="",MJ5="",MK5=""), "", IF(AND(MJ$3=MJ5,MK$3=MK5), 3, IF(AND(MJ$3=MK$3,MJ5=MK5), 2, IF(OR(AND(MJ$3>MK$3,MJ5>MK5), AND(MJ$3<MK$3,MJ5<MK5)), 1, 0)))) | MN5: PABLO CARDENAS | MO5: 1 | MP5: 1 | MQ5: =IF(OR(MO$3="",MP$3="",MO5="",MP5=""), "", IF(AND(MO$3=MO5,MP$3=MP5), 3, IF(AND(MO$3=MP$3,MO5=MP5), 2, IF(OR(AND(MO$3>MP$3,MO5>MP5), AND(MO$3<MP$3,MO5<MP5)), 1, 0)))) | MS5: PABLO CARDENAS | MT5: 0 | MU5: 3 | MV5: =IF(OR(MT$3="",MU$3="",MT5="",MU5=""), "", IF(AND(MT$3=MT5,MU$3=MU5), 3, IF(AND(MT$3=MU$3,MT5=MU5), 2, IF(OR(AND(MT$3>MU$3,MT5>MU5), AND(MT$3<MU$3,MT5<MU5)), 1, 0)))) | MX5: PABLO CARDENAS | MY5: FRANCIA | NA5: PORTUGAL | NC5: INGLATERRA | NE5: COLOMBIA | NG5: KILIAM MBAPE | NI5: =SUM(E5,J5,O5,T5,Y5,AD5,AI5,AN5,AS5,AX5,BC5,BH5,BM5,BR5,,BW5,CB5,CG5,CL5,CQ5,CV5,DA5,DF5,DK5,DP5,DU5,DZ5,EE5,EJ5,EO5,ET5,EY5,FD5,FI5,FN5,FS5,FX5,GC5,GH5,GM5,GR5,GW5,HB5,HG5,HL5,HQ5,HV5,IA5,IF5,IK5,IP5,IU5,IZ5,JE5,JJ5,JO5,JT5,JY5,KD5,KI5,KN5,KS5,KX5,LC5,LH5,LM5,LR5,LW5,MB5,MG5,ML5,MQ5,MV5,MZ5,NB5,ND5,NF5,NH5,) -> 7
A6: 3 | B6: OMAR CARDENAS | C6: 2 | D6: 0 | E6: =IF(OR(C$3="",D$3="",C6="",D6=""), "", IF(AND(C$3=C6,D$3=D6), 3, IF(AND(C$3=D$3,C6=D6), 2, IF(OR(AND(C$3>D$3,C6>D6), AND(C$3<D$3,C6<D6)), 1, 0)))) -> 3 | G6: OMAR CARDENAS | H6: 2 | I6: 2 | J6: =IF(OR(H$3="",I$3="",H6="",I6=""), "", IF(AND(H$3=H6,I$3=I6), 3, IF(AND(H$3=I$3,H6=I6), 2, IF(OR(AND(H$3>I$3,H6>I6), AND(H$3<I$3,H6<I6)), 1, 0)))) -> 0 | L6: OMAR CARDENAS | M6: 1 | N6: 1 | O6: =IF(OR(M$3="",N$3="",M6="",N6=""), "", IF(AND(M$3=M6,N$3=N6), 3, IF(AND(M$3=N$3,M6=N6), 2, IF(OR(AND(M$3>N$3,M6>N6), AND(M$3<N$3,M6<N6)), 1, 0)))) -> 3 | Q6: OMAR CARDENAS | R6: 2 | S6: 1 | T6: =IF(OR(R$3="",S$3="",R6="",S6=""), "", IF(AND(R$3=R6,S$3=S6), 3, IF(AND(R$3=S$3,R6=S6), 2, IF(OR(AND(R$3>S$3,R6>S6), AND(R$3<S$3,R6<S6)), 1, 0)))) -> 1 | V6: OMAR CARDENAS | W6: 0 | X6: 3 | Y6: =IF(OR(W$3="",X$3="",W6="",X6=""), "", IF(AND(W$3=W6,X$3=X6), 3, IF(AND(W$3=X$3,W6=X6), 2, IF(OR(AND(W$3>X$3,W6>X6), AND(W$3<X$3,W6<X6)), 1, 0)))) -> 0 | AA6: OMAR CARDENAS | AB6: 3 | AC6: 1 | AD6: =IF(OR(AB$3="",AC$3="",AB6="",AC6=""), "", IF(AND(AB$3=AB6,AC$3=AC6), 3, IF(AND(AB$3=AC$3,AB6=AC6), 2, IF(OR(AND(AB$3>AC$3,AB6>AC6), AND(AB$3<AC$3,AB6<AC6)), 1, 0)))) -> 0 | AF6: OMAR CARDENAS | AG6: 0 | AH6: 3 | AI6: =IF(OR(AG$3="",AH$3="",AG6="",AH6=""), "", IF(AND(AG$3=AG6,AH$3=AH6), 3, IF(AND(AG$3=AH$3,AG6=AH6), 2, IF(OR(AND(AG$3>AH$3,AG6>AH6), AND(AG$3<AH$3,AG6<AH6)), 1, 0)))) | AK6: OMAR CARDENAS | AL6: 1 | AM6: 2 | AN6: =IF(OR(AL$3="",AM$3="",AL6="",AM6=""), "", IF(AND(AL$3=AL6,AM$3=AM6), 3, IF(AND(AL$3=AM$3,AL6=AM6), 2, IF(OR(AND(AL$3>AM$3,AL6>AM6), AND(AL$3<AM$3,AL6<AM6)), 1, 0)))) | AP6: OMAR CARDENAS | AQ6: 4 | AR6: 0 | AS6: =IF(OR(AQ$3="",AR$3="",AQ6="",AR6=""), "", IF(AND(AQ$3=AQ6,AR$3=AR6), 3, IF(AND(AQ$3=AR$3,AQ6=AR6), 2, IF(OR(AND(AQ$3>AR$3,AQ6>AR6), AND(AQ$3<AR$3,AQ6<AR6)), 1, 0)))) | AU6: OMAR CARDENAS | AV6: 3 | AW6: 1 | AX6: =IF(OR(AV$3="",AW$3="",AV6="",AW6=""), "", IF(AND(AV$3=AV6,AW$3=AW6), 3, IF(AND(AV$3=AW$3,AV6=AW6), 2, IF(OR(AND(AV$3>AW$3,AV6>AW6), AND(AV$3<AW$3,AV6<AW6)), 1, 0)))) | AZ6: OMAR CARDENAS | BA6: 2 | BB6: 2 | BC6: =IF(OR(BA$3="",BB$3="",BA6="",BB6=""), "", IF(AND(BA$3=BA6,BB$3=BB6), 3, IF(AND(BA$3=BB$3,BA6=BB6), 2, IF(OR(AND(BA$3>BB$3,BA6>BB6), AND(BA$3<BB$3,BA6<BB6)), 1, 0)))) | BE6: OMAR CARDENAS | BF6: 2 | BG6: 0 | BH6: =IF(OR(BF$3="",BG$3="",BF6="",BG6=""), "", IF(AND(BF$3=BF6,BG$3=BG6), 3, IF(AND(BF$3=BG$3,BF6=BG6), 2, IF(OR(AND(BF$3>BG$3,BF6>BG6), AND(BF$3<BG$3,BF6<BG6)), 1, 0)))) | BJ6: OMAR CARDENAS | BK6: 5 | BL6: 0 | BM6: =IF(OR(BK$3="",BL$3="",BK6="",BL6=""), "", IF(AND(BK$3=BK6,BL$3=BL6), 3, IF(AND(BK$3=BL$3,BK6=BL6), 2, IF(OR(AND(BK$3>BL$3,BK6>BL6), AND(BK$3<BL$3,BK6<BL6)), 1, 0)))) | BO6: OMAR CARDENAS | BP6: 2 | BQ6: 1 | BR6: =IF(OR(BP$3="",BQ$3="",BP6="",BQ6=""), "", IF(AND(BP$3=BP6,BQ$3=BQ6), 3, IF(AND(BP$3=BQ$3,BP6=BQ6), 2, IF(OR(AND(BP$3>BQ$3,BP6>BQ6), AND(BP$3<BQ$3,BP6<BQ6)), 1, 0)))) | BT6: OMAR CARDENAS | BU6: 0 | BV6: 2 | BW6: =IF(OR(BU$3="",BV$3="",BU6="",BV6=""), "", IF(AND(BU$3=BU6,BV$3=BV6), 3, IF(AND(BU$3=BV$3,BU6=BV6), 2, IF(OR(AND(BU$3>BV$3,BU6>BV6), AND(BU$3<BV$3,BU6<BV6)), 1, 0)))) | BY6: OMAR CARDENAS | BZ6: 1 | CA6: 1 | CB6: =IF(OR(BZ$3="",CA$3="",BZ6="",CA6=""), "", IF(AND(BZ$3=BZ6,CA$3=CA6), 3, IF(AND(BZ$3=CA$3,BZ6=CA6), 2, IF(OR(AND(BZ$3>CA$3,BZ6>CA6), AND(BZ$3<CA$3,BZ6<CA6)), 1, 0)))) | CD6: OMAR CARDENAS | CE6: 3 | CF6: 0 | CG6: =IF(OR(CE$3="",CF$3="",CE6="",CF6=""), "", IF(AND(CE$3=CE6,CF$3=CF6), 3, IF(AND(CE$3=CF$3,CE6=CF6), 2, IF(OR(AND(CE$3>CF$3,CE6>CF6), AND(CE$3<CF$3,CE6<CF6)), 1, 0)))) | CI6: OMAR CARDENAS | CJ6: 0 | CK6: 2 | CL6: =IF(OR(CJ$3="",CK$3="",CJ6="",CK6=""), "", IF(AND(CJ$3=CJ6,CK$3=CK6), 3, IF(AND(CJ$3=CK$3,CJ6=CK6), 2, IF(OR(AND(CJ$3>CK$3,CJ6>CK6), AND(CJ$3<CK$3,CJ6<CK6)), 1, 0)))) | CN6: OMAR CARDENAS | CO6: 2 | CP6: 0 | CQ6: =IF(OR(CO$3="",CP$3="",CO6="",CP6=""), "", IF(AND(CO$3=CO6,CP$3=CP6), 3, IF(AND(CO$3=CP$3,CO6=CP6), 2, IF(OR(AND(CO$3>CP$3,CO6>CP6), AND(CO$3<CP$3,CO6<CP6)), 1, 0)))) | CS6: OMAR CARDENAS | CT6: 2 | CU6: 0 | CV6: =IF(OR(CT$3="",CU$3="",CT6="",CU6=""), "", IF(AND(CT$3=CT6,CU$3=CU6), 3, IF(AND(CT$3=CU$3,CT6=CU6), 2, IF(OR(AND(CT$3>CU$3,CT6>CU6), AND(CT$3<CU$3,CT6<CU6)), 1, 0)))) | CX6: OMAR CARDENAS | CY6: 3 | CZ6: 0 | DA6: =IF(OR(CY$3="",CZ$3="",CY6="",CZ6=""), "", IF(AND(CY$3=CY6,CZ$3=CZ6), 3, IF(AND(CY$3=CZ$3,CY6=CZ6), 2, IF(OR(AND(CY$3>CZ$3,CY6>CZ6), AND(CY$3<CZ$3,CY6<CZ6)), 1, 0)))) | DC6: OMAR CARDENAS | DD6: 2 | DE6: 1 | DF6: =IF(OR(DD$3="",DE$3="",DD6="",DE6=""), "", IF(AND(DD$3=DD6,DE$3=DE6), 3, IF(AND(DD$3=DE$3,DD6=DE6), 2, IF(OR(AND(DD$3>DE$3,DD6>DE6), AND(DD$3<DE$3,DD6<DE6)), 1, 0)))) | DH6: OMAR CARDENAS | DI6: 1 | DJ6: 1 | DK6: =IF(OR(DI$3="",DJ$3="",DI6="",DJ6=""), "", IF(AND(DI$3=DI6,DJ$3=DJ6), 3, IF(AND(DI$3=DJ$3,DI6=DJ6), 2, IF(OR(AND(DI$3>DJ$3,DI6>DJ6), AND(DI$3<DJ$3,DI6<DJ6)), 1, 0)))) | DM6: OMAR CARDENAS | DN6: 1 | DO6: 2 | DP6: =IF(OR(DN$3="",DO$3="",DN6="",DO6=""), "", IF(AND(DN$3=DN6,DO$3=DO6), 3, IF(AND(DN$3=DO$3,DN6=DO6), 2, IF(OR(AND(DN$3>DO$3,DN6>DO6), AND(DN$3<DO$3,DN6<DO6)), 1, 0)))) | DR6: OMAR CARDENAS | DS6: 1 | DT6: 0 | DU6: =IF(OR(DS$3="",DT$3="",DS6="",DT6=""), "", IF(AND(DS$3=DS6,DT$3=DT6), 3, IF(AND(DS$3=DT$3,DS6=DT6), 2, IF(OR(AND(DS$3>DT$3,DS6>DT6), AND(DS$3<DT$3,DS6<DT6)), 1, 0)))) | DW6: OMAR CARDENAS | DX6: 2 | DY6: 0 | DZ6: =IF(OR(DX$3="",DY$3="",DX6="",DY6=""), "", IF(AND(DX$3=DX6,DY$3=DY6), 3, IF(AND(DX$3=DY$3,DX6=DY6), 2, IF(OR(AND(DX$3>DY$3,DX6>DY6), AND(DX$3<DY$3,DX6<DY6)), 1, 0)))) | EB6: OMAR CARDENAS | EC6: 1 | ED6: 1 | EE6: =IF(OR(EC$3="",ED$3="",EC6="",ED6=""), "", IF(AND(EC$3=EC6,ED$3=ED6), 3, IF(AND(EC$3=ED$3,EC6=ED6), 2, IF(OR(AND(EC$3>ED$3,EC6>ED6), AND(EC$3<ED$3,EC6<ED6)), 1, 0)))) | EG6: OMAR CARDENAS | EH6: 1 | EI6: 1 | EJ6: =IF(OR(EH$3="",EI$3="",EH6="",EI6=""), "", IF(AND(EH$3=EH6,EI$3=EI6), 3, IF(AND(EH$3=EI$3,EH6=EI6), 2, IF(OR(AND(EH$3>EI$3,EH6>EI6), AND(EH$3<EI$3,EH6<EI6)), 1, 0)))) | EL6: OMAR CARDENAS | EM6: 2 | EN6: 1 | EO6: =IF(OR(EM$3="",EN$3="",EM6="",EN6=""), "", IF(AND(EM$3=EM6,EN$3=EN6), 3, IF(AND(EM$3=EN$3,EM6=EN6), 2, IF(OR(AND(EM$3>EN$3,EM6>EN6), AND(EM$3<EN$3,EM6<EN6)), 1, 0)))) | EQ6: OMAR CARDENAS | ER6: 1 | ES6: 1 | ET6: =IF(OR(ER$3="",ES$3="",ER6="",ES6=""), "", IF(AND(ER$3=ER6,ES$3=ES6), 3, IF(AND(ER$3=ES$3,ER6=ES6), 2, IF(OR(AND(ER$3>ES$3,ER6>ES6), AND(ER$3<ES$3,ER6<ES6)), 1, 0)))) | EV6: OMAR CARDENAS | EW6: 3 | EX6: 0 | EY6: =IF(OR(EW$3="",EX$3="",EW6="",EX6=""), "", IF(AND(EW$3=EW6,EX$3=EX6), 3, IF(AND(EW$3=EX$3,EW6=EX6), 2, IF(OR(AND(EW$3>EX$3,EW6>EX6), AND(EW$3<EX$3,EW6<EX6)), 1, 0)))) | FA6: OMAR CARDENAS | FB6: 2 | FC6: 2 | FD6: =IF(OR(FB$3="",FC$3="",FB6="",FC6=""), "", IF(AND(FB$3=FB6,FC$3=FC6), 3, IF(AND(FB$3=FC$3,FB6=FC6), 2, IF(OR(AND(FB$3>FC$3,FB6>FC6), AND(FB$3<FC$3,FB6<FC6)), 1, 0)))) | FF6: OMAR CARDENAS | FG6: 2 | FH6: 1 | FI6: =IF(OR(FG$3="",FH$3="",FG6="",FH6=""), "", IF(AND(FG$3=FG6,FH$3=FH6), 3, IF(AND(FG$3=FH$3,FG6=FH6), 2, IF(OR(AND(FG$3>FH$3,FG6>FH6), AND(FG$3<FH$3,FG6<FH6)), 1, 0)))) | FK6: OMAR CARDENAS | FL6: 2 | FM6: 0 | FN6: =IF(OR(FL$3="",FM$3="",FL6="",FM6=""), "", IF(AND(FL$3=FL6,FM$3=FM6), 3, IF(AND(FL$3=FM$3,FL6=FM6), 2, IF(OR(AND(FL$3>FM$3,FL6>FM6), AND(FL$3<FM$3,FL6<FM6)), 1, 0)))) | FP6: OMAR CARDENAS | FQ6: 2 | FR6: 0 | FS6: =IF(OR(FQ$3="",FR$3="",FQ6="",FR6=""), "", IF(AND(FQ$3=FQ6,FR$3=FR6), 3, IF(AND(FQ$3=FR$3,FQ6=FR6), 2, IF(OR(AND(FQ$3>FR$3,FQ6>FR6), AND(FQ$3<FR$3,FQ6<FR6)), 1, 0)))) | FU6: OMAR CARDENAS | FV6: 1 | FW6: 2 | FX6: =IF(OR(FV$3="",FW$3="",FV6="",FW6=""), "", IF(AND(FV$3=FV6,FW$3=FW6), 3, IF(AND(FV$3=FW$3,FV6=FW6), 2, IF(OR(AND(FV$3>FW$3,FV6>FW6), AND(FV$3<FW$3,FV6<FW6)), 1, 0)))) | FZ6: OMAR CARDENAS | GA6: 3 | GB6: 0 | GC6: =IF(OR(GA$3="",GB$3="",GA6="",GB6=""), "", IF(AND(GA$3=GA6,GB$3=GB6), 3, IF(AND(GA$3=GB$3,GA6=GB6), 2, IF(OR(AND(GA$3>GB$3,GA6>GB6), AND(GA$3<GB$3,GA6<GB6)), 1, 0)))) | GE6: OMAR CARDENAS | GF6: 3 | GG6: 0 | GH6: =IF(OR(GF$3="",GG$3="",GF6="",GG6=""), "", IF(AND(GF$3=GF6,GG$3=GG6), 3, IF(AND(GF$3=GG$3,GF6=GG6), 2, IF(OR(AND(GF$3>GG$3,GF6>GG6), AND(GF$3<GG$3,GF6<GG6)), 1, 0)))) | GJ6: OMAR CARDENAS | GK6: 2 | GL6: 0 | GM6: =IF(OR(GK$3="",GL$3="",GK6="",GL6=""), "", IF(AND(GK$3=GK6,GL$3=GL6), 3, IF(AND(GK$3=GL$3,GK6=GL6), 2, IF(OR(AND(GK$3>GL$3,GK6>GL6), AND(GK$3<GL$3,GK6<GL6)), 1, 0)))) | GO6: OMAR CARDENAS | GP6: 0 | GQ6: 1 | GR6: =IF(OR(GP$3="",GQ$3="",GP6="",GQ6=""), "", IF(AND(GP$3=GP6,GQ$3=GQ6), 3, IF(AND(GP$3=GQ$3,GP6=GQ6), 2, IF(OR(AND(GP$3>GQ$3,GP6>GQ6), AND(GP$3<GQ$3,GP6<GQ6)), 1, 0)))) | GT6: OMAR CARDENAS | GU6: 1 | GV6: 1 | GW6: =IF(OR(GU$3="",GV$3="",GU6="",GV6=""), "", IF(AND(GU$3=GU6,GV$3=GV6), 3, IF(AND(GU$3=GV$3,GU6=GV6), 2, IF(OR(AND(GU$3>GV$3,GU6>GV6), AND(GU$3<GV$3,GU6<GV6)), 1, 0)))) | GY6: OMAR CARDENAS | GZ6: 2 | HA6: O | HB6: =IF(OR(GZ$3="",HA$3="",GZ6="",HA6=""), "", IF(AND(GZ$3=GZ6,HA$3=HA6), 3, IF(AND(GZ$3=HA$3,GZ6=HA6), 2, IF(OR(AND(GZ$3>HA$3,GZ6>HA6), AND(GZ$3<HA$3,GZ6<HA6)), 1, 0)))) | HD6: OMAR CARDENAS | HE6: 2 | HF6: 0 | HG6: =IF(OR(HE$3="",HF$3="",HE6="",HF6=""), "", IF(AND(HE$3=HE6,HF$3=HF6), 3, IF(AND(HE$3=HF$3,HE6=HF6), 2, IF(OR(AND(HE$3>HF$3,HE6>HF6), AND(HE$3<HF$3,HE6<HF6)), 1, 0)))) | HI6: OMAR CARDENAS | HJ6: 1 | HK6: 2 | HL6: =IF(OR(HJ$3="",HK$3="",HJ6="",HK6=""), "", IF(AND(HJ$3=HJ6,HK$3=HK6), 3, IF(AND(HJ$3=HK$3,HJ6=HK6), 2, IF(OR(AND(HJ$3>HK$3,HJ6>HK6), AND(HJ$3<HK$3,HJ6<HK6)), 1, 0)))) | HN6: OMAR CARDENAS | HO6: 2 | HP6: 0 | HQ6: =IF(OR(HO$3="",HP$3="",HO6="",HP6=""), "", IF(AND(HO$3=HO6,HP$3=HP6), 3, IF(AND(HO$3=HP$3,HO6=HP6), 2, IF(OR(AND(HO$3>HP$3,HO6>HP6), AND(HO$3<HP$3,HO6<HP6)), 1, 0)))) | HS6: OMAR CARDENAS | HT6: 2 | HU6: 0 | HV6: =IF(OR(HT$3="",HU$3="",HT6="",HU6=""), "", IF(AND(HT$3=HT6,HU$3=HU6), 3, IF(AND(HT$3=HU$3,HT6=HU6), 2, IF(OR(AND(HT$3>HU$3,HT6>HU6), AND(HT$3<HU$3,HT6<HU6)), 1, 0)))) | HX6: OMAR CARDENAS | HY6: 1 | HZ6: 2 | IA6: =IF(OR(HY$3="",HZ$3="",HY6="",HZ6=""), "", IF(AND(HY$3=HY6,HZ$3=HZ6), 3, IF(AND(HY$3=HZ$3,HY6=HZ6), 2, IF(OR(AND(HY$3>HZ$3,HY6>HZ6), AND(HY$3<HZ$3,HY6<HZ6)), 1, 0)))) | IC6: OMAR CARDENAS | ID6: 2 | IE6: 0 | IF6: =IF(OR(ID$3="",IE$3="",ID6="",IE6=""), "", IF(AND(ID$3=ID6,IE$3=IE6), 3, IF(AND(ID$3=IE$3,ID6=IE6), 2, IF(OR(AND(ID$3>IE$3,ID6>IE6), AND(ID$3<IE$3,ID6<IE6)), 1, 0)))) | IH6: OMAR CARDENAS | II6: 1 | IJ6: 0 | IK6: =IF(OR(II$3="",IJ$3="",II6="",IJ6=""), "", IF(AND(II$3=II6,IJ$3=IJ6), 3, IF(AND(II$3=IJ$3,II6=IJ6), 2, IF(OR(AND(II$3>IJ$3,II6>IJ6), AND(II$3<IJ$3,II6<IJ6)), 1, 0)))) | IM6: OMAR CARDENAS | IN6: 1 | IO6: 0 | IP6: =IF(OR(IN$3="",IO$3="",IN6="",IO6=""), "", IF(AND(IN$3=IN6,IO$3=IO6), 3, IF(AND(IN$3=IO$3,IN6=IO6), 2, IF(OR(AND(IN$3>IO$3,IN6>IO6), AND(IN$3<IO$3,IN6<IO6)), 1, 0)))) | IR6: OMAR CARDENAS | IS6: 2 | IT6: 0 | IU6: =IF(OR(IS$3="",IT$3="",IS6="",IT6=""), "", IF(AND(IS$3=IS6,IT$3=IT6), 3, IF(AND(IS$3=IT$3,IS6=IT6), 2, IF(OR(AND(IS$3>IT$3,IS6>IT6), AND(IS$3<IT$3,IS6<IT6)), 1, 0)))) | IW6: OMAR CARDENAS | IX6: 1 | IY6: 2 | IZ6: =IF(OR(IX$3="",IY$3="",IX6="",IY6=""), "", IF(AND(IX$3=IX6,IY$3=IY6), 3, IF(AND(IX$3=IY$3,IX6=IY6), 2, IF(OR(AND(IX$3>IY$3,IX6>IY6), AND(IX$3<IY$3,IX6<IY6)), 1, 0)))) | JB6: OMAR CARDENAS | JC6: 1 | JD6: 2 | JE6: =IF(OR(JC$3="",JD$3="",JC6="",JD6=""), "", IF(AND(JC$3=JC6,JD$3=JD6), 3, IF(AND(JC$3=JD$3,JC6=JD6), 2, IF(OR(AND(JC$3>JD$3,JC6>JD6), AND(JC$3<JD$3,JC6<JD6)), 1, 0)))) | JG6: OMAR CARDENAS | JH6: 2 | JI6: 2 | JJ6: =IF(OR(JH$3="",JI$3="",JH6="",JI6=""), "", IF(AND(JH$3=JH6,JI$3=JI6), 3, IF(AND(JH$3=JI$3,JH6=JI6), 2, IF(OR(AND(JH$3>JI$3,JH6>JI6), AND(JH$3<JI$3,JH6<JI6)), 1, 0)))) | JL6: OMAR CARDENAS | JM6: 0 | JN6: 2 | JO6: =IF(OR(JM$3="",JN$3="",JM6="",JN6=""), "", IF(AND(JM$3=JM6,JN$3=JN6), 3, IF(AND(JM$3=JN$3,JM6=JN6), 2, IF(OR(AND(JM$3>JN$3,JM6>JN6), AND(JM$3<JN$3,JM6<JN6)), 1, 0)))) | JQ6: OMAR CARDENAS | JR6: 1 | JS6: 2 | JT6: =IF(OR(JR$3="",JS$3="",JR6="",JS6=""), "", IF(AND(JR$3=JR6,JS$3=JS6), 3, IF(AND(JR$3=JS$3,JR6=JS6), 2, IF(OR(AND(JR$3>JS$3,JR6>JS6), AND(JR$3<JS$3,JR6<JS6)), 1, 0)))) | JV6: OMAR CARDENAS | JW6: 0 | JX6: 3 | JY6: =IF(OR(JW$3="",JX$3="",JW6="",JX6=""), "", IF(AND(JW$3=JW6,JX$3=JX6), 3, IF(AND(JW$3=JX$3,JW6=JX6), 2, IF(OR(AND(JW$3>JX$3,JW6>JX6), AND(JW$3<JX$3,JW6<JX6)), 1, 0)))) | KA6: OMAR CARDENAS | KB6: 1 | KC6: 1 | KD6: =IF(OR(KB$3="",KC$3="",KB6="",KC6=""), "", IF(AND(KB$3=KB6,KC$3=KC6), 3, IF(AND(KB$3=KC$3,KB6=KC6), 2, IF(OR(AND(KB$3>KC$3,KB6>KC6), AND(KB$3<KC$3,KB6<KC6)), 1, 0)))) | KF6: OMAR CARDENAS | KG6: 1 | KH6: 1 | KI6: =IF(OR(KG$3="",KH$3="",KG6="",KH6=""), "", IF(AND(KG$3=KG6,KH$3=KH6), 3, IF(AND(KG$3=KH$3,KG6=KH6), 2, IF(OR(AND(KG$3>KH$3,KG6>KH6), AND(KG$3<KH$3,KG6<KH6)), 1, 0)))) | KK6: OMAR CARDENAS | KL6: 1 | KM6: 0 | KN6: =IF(OR(KL$3="",KM$3="",KL6="",KM6=""), "", IF(AND(KL$3=KL6,KM$3=KM6), 3, IF(AND(KL$3=KM$3,KL6=KM6), 2, IF(OR(AND(KL$3>KM$3,KL6>KM6), AND(KL$3<KM$3,KL6<KM6)), 1, 0)))) | KP6: OMAR CARDENAS | KQ6: 1 | KR6: 1 | KS6: =IF(OR(KQ$3="",KR$3="",KQ6="",KR6=""), "", IF(AND(KQ$3=KQ6,KR$3=KR6), 3, IF(AND(KQ$3=KR$3,KQ6=KR6), 2, IF(OR(AND(KQ$3>KR$3,KQ6>KR6), AND(KQ$3<KR$3,KQ6<KR6)), 1, 0)))) | KU6: OMAR CARDENAS | KV6: 2 | KW6: 2 | KX6: =IF(OR(KV$3="",KW$3="",KV6="",KW6=""), "", IF(AND(KV$3=KV6,KW$3=KW6), 3, IF(AND(KV$3=KW$3,KV6=KW6), 2, IF(OR(AND(KV$3>KW$3,KV6>KW6), AND(KV$3<KW$3,KV6<KW6)), 1, 0)))) | KZ6: OMAR CARDENAS | LA6: 0 | LB6: 2 | LC6: =IF(OR(LA$3="",LB$3="",LA6="",LB6=""), "", IF(AND(LA$3=LA6,LB$3=LB6), 3, IF(AND(LA$3=LB$3,LA6=LB6), 2, IF(OR(AND(LA$3>LB$3,LA6>LB6), AND(LA$3<LB$3,LA6<LB6)), 1, 0)))) | LE6: OMAR CARDENAS | LF6: 1 | LG6: 2 | LH6: =IF(OR(LF$3="",LG$3="",LF6="",LG6=""), "", IF(AND(LF$3=LF6,LG$3=LG6), 3, IF(AND(LF$3=LG$3,LF6=LG6), 2, IF(OR(AND(LF$3>LG$3,LF6>LG6), AND(LF$3<LG$3,LF6<LG6)), 1, 0)))) | LJ6: OMAR CARDENAS | LK6: 0 | LL6: 2 | LM6: =IF(OR(LK$3="",LL$3="",LK6="",LL6=""), "", IF(AND(LK$3=LK6,LL$3=LL6), 3, IF(AND(LK$3=LL$3,LK6=LL6), 2, IF(OR(AND(LK$3>LL$3,LK6>LL6), AND(LK$3<LL$3,LK6<LL6)), 1, 0)))) | LO6: OMAR CARDENAS | LP6: 1 | LQ6: 0 | LR6: =IF(OR(LP$3="",LQ$3="",LP6="",LQ6=""), "", IF(AND(LP$3=LP6,LQ$3=LQ6), 3, IF(AND(LP$3=LQ$3,LP6=LQ6), 2, IF(OR(AND(LP$3>LQ$3,LP6>LQ6), AND(LP$3<LQ$3,LP6<LQ6)), 1, 0)))) | LT6: OMAR CARDENAS | LU6: 0 | LV6: 3 | LW6: =IF(OR(LU$3="",LV$3="",LU6="",LV6=""), "", IF(AND(LU$3=LU6,LV$3=LV6), 3, IF(AND(LU$3=LV$3,LU6=LV6), 2, IF(OR(AND(LU$3>LV$3,LU6>LV6), AND(LU$3<LV$3,LU6<LV6)), 1, 0)))) | LY6: OMAR CARDENAS | LZ6: 2 | MA6: 1 | MB6: =IF(OR(LZ$3="",MA$3="",LZ6="",MA6=""), "", IF(AND(LZ$3=LZ6,MA$3=MA6), 3, IF(AND(LZ$3=MA$3,LZ6=MA6), 2, IF(OR(AND(LZ$3>MA$3,LZ6>MA6), AND(LZ$3<MA$3,LZ6<MA6)), 1, 0)))) | MD6: OMAR CARDENAS | ME6: 1 | MF6: 1 | MG6: =IF(OR(ME$3="",MF$3="",ME6="",MF6=""), "", IF(AND(ME$3=ME6,MF$3=MF6), 3, IF(AND(ME$3=MF$3,ME6=MF6), 2, IF(OR(AND(ME$3>MF$3,ME6>MF6), AND(ME$3<MF$3,ME6<MF6)), 1, 0)))) | MI6: OMAR CARDENAS | MJ6: 0 | MK6: 1 | ML6: =IF(OR(MJ$3="",MK$3="",MJ6="",MK6=""), "", IF(AND(MJ$3=MJ6,MK$3=MK6), 3, IF(AND(MJ$3=MK$3,MJ6=MK6), 2, IF(OR(AND(MJ$3>MK$3,MJ6>MK6), AND(MJ$3<MK$3,MJ6<MK6)), 1, 0)))) | MN6: OMAR CARDENAS | MO6: 1 | MP6: 1 | MQ6: =IF(OR(MO$3="",MP$3="",MO6="",MP6=""), "", IF(AND(MO$3=MO6,MP$3=MP6), 3, IF(AND(MO$3=MP$3,MO6=MP6), 2, IF(OR(AND(MO$3>MP$3,MO6>MP6), AND(MO$3<MP$3,MO6<MP6)), 1, 0)))) | MS6: OMAR CARDENAS | MT6: 0 | MU6: 3 | MV6: =IF(OR(MT$3="",MU$3="",MT6="",MU6=""), "", IF(AND(MT$3=MT6,MU$3=MU6), 3, IF(AND(MT$3=MU$3,MT6=MU6), 2, IF(OR(AND(MT$3>MU$3,MT6>MU6), AND(MT$3<MU$3,MT6<MU6)), 1, 0)))) | MX6: OMAR CARDENAS | MY6: PORTUGAL | NA6: FRANCIA | NC6: ESPAÑA | NE6: INGLATERRA | NG6: KILIAM MBAPE | NI6: =SUM(E6,J6,O6,T6,Y6,AD6,AI6,AN6,AS6,AX6,BC6,BH6,BM6,BR6,,BW6,CB6,CG6,CL6,CQ6,CV6,DA6,DF6,DK6,DP6,DU6,DZ6,EE6,EJ6,EO6,ET6,EY6,FD6,FI6,FN6,FS6,FX6,GC6,GH6,GM6,GR6,GW6,HB6,HG6,HL6,HQ6,HV6,IA6,IF6,IK6,IP6,IU6,IZ6,JE6,JJ6,JO6,JT6,JY6,KD6,KI6,KN6,KS6,KX6,LC6,LH6,LM6,LR6,LW6,MB6,MG6,ML6,MQ6,MV6,MZ6,NB6,ND6,NF6,NH6,) -> 7
